Workbook
Name BUSCAR: RECIBO!$J$4:$K$4

Sheet RECIBO
C2: Teléfono: 844 413 0504
C4: Whatsapp: 844 443 9987
J5: {=IFERROR(VLOOKUP($J$4,{DATABASE!B2:B27,DATABASE!A2:A27},2,FALSE),"-")} -> -
B7: FECHA | C7: =TODAY() -> 46084
C8: DD/MM/AAAA
B10: No. INDENTIFICACIÓN
B11: NOMBRE COMPLETO | D11: =IFERROR(VLOOKUP($D$10,DATABASE!A2:L27,2,FALSE),"-") -> -
B12: TELEFONO O CELULAR | D12: =IFERROR(VLOOKUP($D$10,DATABASE!A2:L27,5,FALSE),"-") -> -
B13: TERAPEUTA
B14: DETALLES DE PAGO
B15: UBICACIÓN | D15: FACTURA | F15: FORMA DE PAGO
B16: DESCRIPCIÓN DEL SERVICIO | E16: CANTIDAD | F16: VALOR UNITARIO | G16: IMPORTE
F17: =IFERROR(VLOOKUP(B17,catalogo!$B$1:$D$35,2,FALSE),"") | G17: =E17*F17 -> 0
F18: =IFERROR(VLOOKUP(B18,catalogo!$B$1:$D$35,2,FALSE),"") | G18: =E18*F18 -> 0
F19: =IFERROR(VLOOKUP(B19,catalogo!$B$1:$D$35,2,FALSE),"") | G19: =E19*F19 -> 0
F20: =IFERROR(VLOOKUP(B20,catalogo!$B$1:$D$35,2,FALSE),"") | G20: =E20*F20 -> 0
F21: =IFERROR(VLOOKUP(B21,catalogo!$B$1:$D$35,2,FALSE),"") | G21: =E21*F21 -> 0
E22: DESCUENTO
E23: SUBTOTAL | G23: =SUM(G17:G21)-G22 -> 0
E24: COMISIÓN POR PAGO CON TARJETA | G24: =IF(G15="TARJETA", G23 * 0.03, "N/A") -> N/A
E25: IVA | G25: =IF(E15="SI",G23*0.16,"N/A") -> N/A
E26: TOTAL | G26: =SUM(G23:G25) -> 0

Sheet DATABASE
B1: NOMBRE | C1: FECHA DE INICIO | D1: LUGAR | E1: CELULAR | F1: PARENTESCOS | G1: TERAPEUTA | H1: TIPO DE TERAPIA | I1: DIVISIÓN | J1: COSTO | K1: PAGO TERAPEUTA | L1: CULMINACION DE SESIONES
A2: 100 | B2: jesus ignacio galindo | C2: 45054 | E2: dennise giasa | G2: Yulior Ramírez | H2: Individual | I2: N/A | L2: BAJA
A3: 101 | B3: Mely Davila ibarra | C3: 45067 | E3: Dennise giasa | G3: Ale Almanza | H3: Pareja | I3: N/A | L3: No hay contacto
A4: 102 | B4: Wendolyne Carrasco | C4: 45079 | E4: 8443679448 | G4: Karina Montoya | H4: Individual | I4: N/A | L4: No hay contacto
A5: 103 | B5: Nallely Pedrosa | C5: 45081 | E5: 8442908503 | G5: Víctor Gaytán | H5: Individual | I5: N/A | K5: 200 | L5: No hay contacto
A6: 104 | B6: Juany Arellano | C6: 45082 | G6: Arcadio | H6: Individual | I6: N/A | L6: BAJA
A7: 105 | B7: Madeline Rangel | C7: 45082 | E7: 8442782384 | G7: Arcadio | H7: Individual | I7: N/A | L7: BAJA
A8: 106 | B8: Lesly Sarahi Espinosa Rios | C8: 45083 | E8: 8443882328 | G8: Arcadio | H8: Individual | I8: N/A | L8: BAJA
A9: 107 | B9: Roxana Martínez | C9: 45083 | E9: 8445405379 | G9: Ale Almanza | H9: Pareja | I9: N/A | K9: 250 | L9: No hay contacto
A10: 108 | B10: Valeria Monserrat González López | C10: 45083 | D10: Guanajuato | E10: 8447643481 | G10: Lic. Javier Martinez | H10: Individual | I10: INTRA | J10: $380 | L10: Activo
A11: 109 | B11: Regina Samantha Leza | C11: 45085 | E11: 8443501370 | G11: Víctor Gaytán | H11: Individual | I11: N/A | K11: 250 | L11: No hay contacto
A12: 110 | B12: melissa de la paz ovalle | C12: 45086 | E12: 8446076392 | G12: Yulior Ramírez | H12: Individual | I12: N/A | K12: 50 | L12: No hay contacto
A13: 111 | B13: Fernanda Medina | C13: 45094 | E13: 8442055892 | G13: Javier Martinez | H13: Individual | I13: N/A | J13: $380 | K13: 250 | L13: No hay contacto
A14: 112 | B14: Liceide Cardenas | C14: 45095 | E14: 8441298997 | G14: Pablo Acosta | H14: Individual | I14: N/A | L14: No hay contacto
A15: 113 | B15: Rosa Vazquez | C15: 45095 | E15: 8443180543 | G15: Víctor Gaytán | H15: Individual | I15: Servicio Gratuito | K15: 250 | L15: No hay contacto
A16: 114 | B16: Oscar Pedrosa | C16: 45096 | G16: Arcadio | H16: Individual | I16: N/A | K16: 250 | L16: BAJA
A17: 115 | B17: Luis Carlos Olvera | C17: 45100 | E17: 8443534681 | G17: Víctor Gaytán | H17: Individual | I17: N/A | L17: No hay contacto
A18: 116 | B18: Yasmin constante | C18: 45103 | E18: 8448708731 | G18: Pablo Acosta | H18: Breve | I18: N/A | L18: No hay contacto
A19: 117 | B19: LAURA SANCHEZ | C19: 45104 | E19: 8442652903 | G19: Ale Almanza | H19: Infantil | I19: N/A | L19: No hay contacto
A20: 118 | B20: Maria Guadalupe Peña | C20: 45104 | E20: 8441016267 | G20: Arcadio | H20: Individual | I20: N/A | L20: No hay contacto
A21: 119 | B21: Rafael Antonio Lopez Torrres | C21: 45104 | E21: 8442023767 | G21: Ale Almanza | H21: Familiar/Individual | I21: N/A | J21: 807 | K21: Empresa | L21: No hay contacto
A22: 120 | B22: Ramiro Cedillo | C22: 45107 | E22: 8444528980 | G22: Pablo Acosta | H22: Individual | I22: N/A | K22: Sueldo base | L22: No hay contacto
A23: 121 | B23: LUISA MOYA | C23: 45108 | E23: 8443188978 | G23: Arcadio | H23: Individual | I23: $170 | L23: No hay contacto
A24: 122 | B24: Kattya Valeria Vazquez Ortiz | C24: 45109 | E24: 8442034920 | G24: Yulior Ramírez | H24: Individual | I24: N/A | L24: No hay contacto
A25: 123 | B25: sandra fabiola reyna | C25: 45109 | E25: 8442391084 | G25: Yulior Ramírez | H25: Individual | I25: $250 | K25: 200 | L25: No hay contacto
A26: 124 | B26: Sofia de Lourdes Medina | C26: 45109 | E26: 8442432140 | G26: Ale Almanza | H26: Individual | I26: N/A | K26: Sueldo base | L26: No hay contacto
A27: 125 | B27: Ximena Abigail Coronado Torres | C27: 45110 | E27: 8444968680 | G27: Ale Almanza | H27: Infantil | I27: N/A | K27: 9 | L27: No hay contacto
A28: 126 | B28: Maricruz Ibarra Ramírez | C28: 45111 | E28: 8441769041 | G28: Arcadio | H28: Individual | I28: N/A | K28: 200 | L28: No hay contacto
A29: 127 | B29: Samantha Camacho | C29: 45120 | G29: Víctor Gaytán | H29: Individual | I29: N/A | K29: 200 | L29: No hay contacto
A30: 128 | B30: Karla Gabriela Quiroz | C30: 45124 | E30: 8442991953 | G30: Víctor Gaytán | L30: BAJA
A31: 129 | B31: Margarita Lizárraga | C31: 45128 | E31: 8443933370 | G31: Víctor Gaytán | H31: Individual | I31: N/A | L31: No hay contacto
A32: 130 | B32: Perla Cecilia Carrillo | C32: 45131 | E32: 8441385491 | G32: Víctor Gaytán | L32: No hay contacto
A33: 131 | B33: Raul Lopez | C33: 45131 | E33: 8445876432 | G33: Víctor Gaytán | K33: 250 | L33: No hay contacto
A34: 132 | B34: Marcela R. Cordova | C34: 45137 | E34: 8443216217 | G34: Víctor Gaytán | L34: No hay contacto
A35: 133 | B35: Maria Yolanda Morales | C35: 45142 | E35: 8446006639 | G35: Arcadio | K35: 200 | L35: No hay contacto
A36: 134 | B36: Yesenia Gzlz. Hdz | C36: 45142 | E36: 5539072567 | G36: Víctor Gaytán | L36: No hay contacto
A37: 135 | B37: Ulises Ramirez | C37: 44050 | E37: 8442774903 | G37: Arcadio | L37: No hay contacto
A38: 136 | B38: Sergio Isaac Morado García | C38: 44051 | E38: 8443400214 | G38: Arcadio | K38: EMPRESA | L38: No hay contacto
A39: 137 | B39: Pamela Guadalupe Cabral Perez (Reyna) | C39: 45148 | E39: 8443120567 | G39: Víctor Gaytán | K39: 250 | L39: No hay contacto
A40: 138 | B40: Sofia Elena Flores Escobedo | C40: 45150 | E40: 8442218395 | G40: Arcadio | K40: 350 | L40: No hay contacto
...

Sheet Convenios
B3: CONVENIO | C3: CATEGORIA | D3: $ | E3: Detalles
B4: Academia INTRA | C4: Escuela | D4: Individual e infantil: $350 Especialización, Pareja, Familiar: $400 Médica $700
B5: Cáritas de Saltillo | C5: Asociación civil | D5: Canalizados: 25% de descuento Colaboradores: 35% de descuento
B6: Colegio Americano | C6: Escuela | D6: Individual e infantil: $300 Pareja, Familiar: $350 Medica: 500 Psiquiatrica: 770
B7: Dorothea | C7: Escuela | D7: Individual e infantil: $350 Pareja, Familiar: $350 Medica: 500 Psiquiatrica: 770
B8: EDUCEM | C8: Escuela | D8: Individual e infantil: $300 Pareja, Familiar: $350 Medica: 500 Psiquiatrica: 770
B9: Facultad de psicologia | C9: Escuela | D9: Individual e infantil: $300 Pareja, Familiar: $350 Medica: 500 Psiquiatrica: 770
B10: Fiscalía Coahuila | C10: Instancia de gobierno | D10: Individual e infantil: $300 Pareja, Familiar: $350 Medica: 500 Psiquiatrica: 770 | E10: Fiscalía General del Estado de Coahuila
B11: Fundación Erika | C11: Asociación civil | D11: Individual e infantil: $300 Pareja, Familiar: $350 Medica: 500 Psiquiatrica: 770
B12: GIASA | C12: Empresa | D12: Paga la empresa | E12: incluye individual o infantil, solo familiares directos (otro servicio ocupan autorización de RH)
B13: Greenhill | C13: Escuela | D13: Individual e infantil: $300 Pareja, Familiar: $350 Medica: 500
B14: iFOOD | C14: Empresa | D14: Paga la empresa, susana nos comparte el nombre del proximo paciente (350 ya incluye iva) | E14: Incluye terapia individual, infantil y de pareja
B15: INSUNTE | C15: Escuela | D15: Individual e infantil: $300 Pareja, Familiar: $350 Medica: 500 Psiquiatrica: 770
B16: NEAPCO | C16: Empresa | D16: Paga la empresa, entregan pase | E16: Incluye todos los servicios. (evaluaciones si son varias sesiones, pedir vale por hora)
B17: Particular | C17: INTRA | D17: individual 420, infantil 480, pareja 520, familiar, 550, medica 550, psiquiatrica 850
B18: Secretaria de Salud | C18: Instancia de gobierno | D18: Individual e infantil: $300 Pareja, Familiar: $350 Medica: 500 Psiquiatrica: 770
B19: Trabajo social | C19: Escuela | D19: Individual e infantil: $300 Pareja, Familiar: $350 Medica: 500 Psiquiatrica: 770
B20: UANE | C20: Escuela | D20: Individual e infantil: $300 Pareja, Familiar: $350 Medica: 500 Psiquiatrica: 770
B21: UNIVAS | C21: Escuela | D21: Individual e infantil: $300 Pareja, Familiar: $350 Medica: 500 Psiquiatrica: 770
B22: USAER | C22: Instancia de gobierno | D22: Individual y Familiar 200, cualquier otro servicio 20%
B23: Colaboradores | C23: INTRA | D23: individual: 250
B24: UTS | C24: Escuela | D24: Individual e infantil: $300 Pareja, Familiar: $350 Medica: 500 Psiquiatrica: 770
B25: Vizcaya | C25: Escuela | D25: Individual e infantil: $300 Pareja, Familiar: $350 Medica: 500 Psiquiatrica: 770

Sheet INGRESOS
A1: fecha | B1: NO. | C1: SERVICIO | D1: TERAPEUTA | E1: PACIENTE | F1: UBICACION | G1: FACTURA | H1: FORMA DE PAGO | I1: SUBTOTAL | J1: COMISIÓN PAGO TARJETA | K1: IVA | L1: TOTAL | M1: pago a terapeuta | N1: BANCO | O1: INGRESO REAL
A2: 45971 | B2: 2221 | C2: Evaluación Wisc | E2: Jorge Arturo Rodríguez Perales | I2: 0 | J2: N/A | K2: N/A | L2: 0 | N2: =L2-M2 -> 0
A3: 45804 | B3: 2097 | C3: Individual | D3: Rosy Macias | E3: Wendy Alexandra Briones Rodríguez | F3: Morelos | G3: NO | H3: EFECTIVO | I3: 420 | J3: N/A | K3: N/A | L3: 420 | N3: =L3-M3 -> 420
A4: 45804 | B4: 819 | C4: Individual | D4: Yessica Leija | E4: Alexa Osorio | F4: Guanajuato | G4: NO | H4: TARJETA | I4: 125 | J4: 3.75 | K4: N/A | L4: 128.75 | N4: =L4-M4 -> 128.75
A5: 45804 | B5: 2098 | C5: Individual | D5: Maricela Sena | E5: Rafael Hassan de las Fuentes Lugo | F5: Guanajuato | G5: NO | H5: TARJETA | I5: 420 | J5: 12.6 | K5: N/A | L5: 432.6 | N5: =L5-M5 -> 432.6
A6: 45804 | B6: 2079 | C6: Individual | D6: Rosy Macias | E6: Paola Guadalupe Rodríguez Pequeño | F6: Morelos | G6: NO | H6: EFECTIVO | I6: 420 | J6: N/A | K6: N/A | L6: 420 | N6: =L6-M6 -> 420
A7: 45804 | B7: 2078 | C7: Individual | D7: Rosy Macias | E7: Jorge Alfonso Gamboa Saldaña | F7: Morelos | G7: NO | H7: EFECTIVO | I7: 420 | J7: N/A | K7: N/A | L7: 420 | N7: =L7-M7 -> 420
A8: 45804 | B8: 1229 | C8: Individual | D8: Rosy Macias | E8: ximena Guadalupe Gonzalez | F8: Morelos | G8: NO | H8: EFECTIVO | I8: 420 | J8: N/A | K8: N/A | L8: 420 | N8: =L8-M8 -> 420
A9: 45803 | B9: 2106 | C9: Pareja | D9: Daniel Salazar | E9: Juan Manuel Cisneros Silva y Claudia Leticia Manzanares Lumbreras | F9: Morelos | G9: NO | I9: 520 | J9: N/A | K9: N/A | L9: 520 | N9: =L9-M9 -> 520
A10: 45803 | B10: 856 | C10: Individual | D10: José Arcadio | E10: Christian Valencia | F10: Praderas | G10: NO | H10: TRANSFERENCIA | I10: 420 | J10: N/A | K10: N/A | L10: 420 | N10: =L10-M10 -> 420
A11: 45803 | B11: 2012 | C11: Individual | D11: Benjamin Villagomez | E11: Maricela Sena García | F11: Guanajuato | G11: NO | H11: EFECTIVO | I11: 300 | J11: N/A | K11: N/A | L11: 300 | N11: =L11-M11 -> 300
A12: 45803 | B12: 1736 | C12: Individual | D12: Daniel Salazar | E12: Carlos Monsivais | F12: TEAMS | G12: NO | H12: TRANSFERENCIA | I12: 400 | J12: N/A | K12: N/A | L12: 400 | N12: =L12-M12 -> 400
A13: 45803 | B13: 2105 | C13: Pareja | D13: José Arcadio | E13: Luis Escobedo Flores y Mariana Castañeda Garcia | F13: Praderas | G13: NO | I13: 520 | J13: N/A | K13: N/A | L13: 520 | N13: =L13-M13 -> 520
A14: 45803 | B14: 1827 | C14: Individual | D14: Alondra Escalon | E14: Andrea Guadalupe Padilla Resendiz | F14: Praderas | G14: NO | H14: SEGURO | I14: 0 | J14: N/A | K14: N/A | L14: 0 | N14: =L14-M14 -> 0
A15: 45803 | B15: 2029 | C15: Evaluación neuropsicológica | D15: Dante Zertuche | E15: Franscisco Daniel Lopez | F15: Morelos | G15: NO | I15: 1850 | J15: N/A | K15: N/A | L15: 1850 | N15: =L15-M15 -> 1850
A16: 45803 | B16: 783 | C16: Individual | D16: Dante Zertuche | E16: Samuel Lozano | F16: Morelos | G16: NO | I16: 400 | J16: N/A | K16: N/A | L16: 400 | N16: =L16-M16 -> 400
A17: 45803 | B17: 1789 | C17: Empresa Atención Psicológica NEAPCO | D17: Dante Zertuche | E17: Dominick Ronaldo García Sánchez | F17: Morelos | G17: NO | H17: EMPRESA | I17: 0 | J17: N/A | K17: N/A | L17: 0 | N17: =L17-M17 -> 0
A18: 45801 | B18: 2062 | C18: Individual | D18: Benjamin Villagomez | E18: David Alberto Sanchez Ramirez | F18: Guanajuato | G18: NO | H18: TARJETA | I18: 420 | J18: 12.6 | K18: N/A | L18: 432.6 | N18: =L18-M18 -> 432.6
A19: 45801 | B19: 796 | C19: Infantil | D19: Daniela Sarmiento | E19: Iker Emiliano Osorio | F19: TEAMS | G19: NO | I19: 125 | J19: N/A | K19: N/A | L19: 125 | N19: =L19-M19 -> 125
A20: 45801 | B20: 2096 | C20: Individual | D20: Benjamin Villagomez | E20: Christian Michelle Calvillo Franco | F20: Guanajuato | G20: NO | H20: EFECTIVO | I20: 420 | J20: N/A | K20: N/A | L20: 420 | N20: =L20-M20 -> 420
A21: 45801 | B21: 2087 | C21: Medica | D21: Enrique Luna | E21: Mario Zamarripa | F21: Guanajuato | G21: NO | I21: 600 | J21: N/A | K21: N/A | L21: 600 | N21: =L21-M21 -> 600
A22: 45801 | B22: 2093 | C22: Individual | D22: Daniela Sarmiento | E22: Izamar Alejandra Rosales Vega | F22: Praderas | G22: NO | H22: EFECTIVO | I22: 250 | J22: N/A | K22: N/A | L22: 250 | N22: =L22-M22 -> 250
A23: 45801 | B23: 2053 | C23: Individual | D23: Daniel Salazar | E23: Olga Liliana De la Canal Galindo | F23: Morelos | G23: NO | H23: EFECTIVO | I23: 420 | J23: N/A | K23: N/A | L23: 420 | N23: =L23-M23 -> 420
A24: 45801 | B24: 2004 | C24: Individual | D24: José Arcadio | E24: Luis Diego Lopez Oropeza | F24: Praderas | G24: NO | H24: EFECTIVO | I24: 420 | J24: N/A | K24: N/A | L24: 420 | N24: =L24-M24 -> 420
A25: 45801 | B25: 2087 | C25: Individual | D25: Javier Martínez | E25: Mario Zamarripa | F25: Guanajuato | G25: NO | I25: 300 | J25: N/A | K25: N/A | L25: 300 | N25: =L25-M25 -> 300
A26: 45800 | B26: 2087 | C26: Individual | D26: Maricela Sena | E26: Mario Zamarripa | F26: Guanajuato | G26: NO | H26: EFECTIVO | I26: 300 | J26: N/A | K26: N/A | L26: 300 | N26: =L26-M26 -> 300
A27: 45800 | B27: 622 | C27: Empresa Atención Psicológica NEAPCO | D27: Psicólogos por hora | E27: Luis Contreras | F27: Consultorio externo | G27: NO | H27: EMPRESA | I27: 0 | J27: N/A | K27: N/A | L27: 0 | N27: =L27-M27 -> 0
A28: 45800 | B28: 1402 | C28: Individual | D28: Maria Amancio | E28: Assef Lara Ibarra | F28: TEAMS | G28: NO | H28: PASE | I28: 0 | J28: N/A | K28: N/A | L28: 0 | N28: =L28-M28 -> 0
A29: 45799 | B29: 2103 | C29: Empresa Atención Psicológica NEAPCO | D29: Gloria Sarmiento | E29: Carlos Alejandro Olvera flores | F29: Colinas | G29: NO | H29: EMPRESA | I29: 0 | J29: N/A | K29: N/A | L29: 0 | N29: =L29-M29 -> 0
A30: 45799 | B30: 2102 | C30: Individual | D30: Ana Juarez | E30: Amarantah Hernández | F30: TEAMS | G30: NO | H30: TRANSFERENCIA | I30: 300 | J30: N/A | K30: N/A | L30: 300 | N30: =L30-M30 -> 300
A31: 45799 | B31: 2059 | C31: GIASA | D31: Gloria Sarmiento | E31: Maricela Herrera | F31: Colinas | G31: NO | H31: EMPRESA | I31: 0 | J31: N/A | K31: N/A | L31: 0 | N31: =L31-M31 -> 0
A32: 45799 | B32: 2050 | C32: Individual | D32: José Arcadio | E32: Magaly Martínez | F32: Praderas | G32: NO | H32: EFECTIVO | I32: 350 | J32: N/A | K32: N/A | L32: 350 | N32: =L32-M32 -> 350
A33: 45799 | C33: Renta de espacios - Asociados | D33: Alondra Escalon | E33: - | F33: Praderas | G33: NO | H33: EFECTIVO | I33: 125 | J33: N/A | K33: N/A | L33: 125 | N33: =L33-M33 -> 125
A34: 45799 | B34: 2081 | C34: Individual | D34: Gloria Sarmiento | E34: Leonel Abraham Galindo Garay | F34: Colinas | G34: NO | I34: 420 | J34: N/A | K34: N/A | L34: 420 | N34: =L34-M34 -> 420
A35: 45799 | B35: 1887 | C35: Individual | D35: Javier Martínez | E35: Sandra Garcia Davila | F35: Guanajuato | G35: NO | I35: 400 | J35: N/A | K35: N/A | L35: 400 | N35: =L35-M35 -> 400
A36: 45799 | B36: 1833 | C36: Individual | D36: Yessica Leija | E36: Vianney González | F36: Guanajuato | G36: NO | H36: EFECTIVO | I36: 400 | J36: N/A | K36: N/A | L36: 400 | N36: =L36-M36 -> 400
A37: 45799 | B37: 1082 | C37: Individual | D37: Maria Amancio | E37: Edwin Resendiz | F37: TEAMS | G37: NO | H37: PASE | I37: 350 | J37: N/A | K37: N/A | L37: 350 | N37: =L37-M37 -> 350
A38: 45798 | B38: 2010 | C38: Individual | D38: Benjamin Villagomez | E38: Jhonatan David Romero Martínez | F38: Guanajuato | G38: NO | H38: EFECTIVO | I38: 420 | J38: N/A | K38: N/A | L38: 420 | N38: =L38-M38 -> 420
A39: 45798 | B39: 2101 | C39: Individual | D39: Benjamin Villagomez | E39: Ana Ma Servin Domínguez | F39: Consultorio externo | G39: NO | H39: EFECTIVO | I39: 570 | J39: N/A | K39: N/A | L39: 570 | N39: =L39-M39 -> 570
A40: 45798 | B40: 1444 | C40: Individual | D40: Javier Martínez | E40: Fernando Medina | F40: Guanajuato | G40: NO | H40: TARJETA | I40: 400 | J40: 12 | K40: N/A | L40: 412 | N40: =L40-M40 -> 412
...

Sheet Costos Normales
B3: Servicios Individuales
B4: Individual | C4: 420
B5: Infantil | C5: 480
B6: Psicotanatologia | C6: 400
B7: Hipnosis Clinica | C7: 550
B8: Equinoterapia | C8: 900
B9: Consulta Medica | C9: 600
B10: Consulta Medica en Salud Mental | C10: 850
B11: Consulta Psiquiatrica | C11: 1000
B12: Servicios Grupales
B13: Pareja | C13: 520
B14: Familiar | C14: 550
B15: Otros Servicios
B16: Consulta Nutricional | C16: 550
B17: Evaluación Neuropsicologica | C17: $420
B18: Evaluación Psicologica | C18: 1200 - 2400
B19: Certificado Mascota de Apoyo Emocional | C19: 1900
B20: Constancia de Proceso | C20: 120
B21: Informe Psicologico | C21: 1900

Sheet Ene 26
B1: 46023 | L1: =B1+1 -> 46024 | V1: =L1+1 -> 46025 | AF1: =V1+1 -> 46026 | AP1: =AF1+1 -> 46027 | AZ1: =AP1+1 -> 46028 | BJ1: =AZ1+1 -> 46029 | BT1: =BJ1+1 -> 46030 | CD1: =BT1+1 -> 46031 | CN1: =CD1+1 -> 46032 | CX1: =CN1+1 -> 46033 | DH1: =CX1+1 -> 46034 | DR1: =DH1+1 -> 46035 | EB1: =DR1+1 -> 46036 | EL1: =EB1+1 -> 46037 | EV1: =EL1+1 -> 46038 | FF1: =EV1+1 -> 46039 | FP1: =FF1+1 -> 46040 | FZ1: =FP1+1 -> 46041 | GJ1: =FZ1+1 -> 46042 | GT1: =GJ1+1 -> 46043 | HD1: =GT1+1 -> 46044 | HN1: =HD1+1 -> 46045 | HX1: =HN1+1 -> 46046 | IH1: =HX1+1 -> 46047 | IR1: =IH1+1 -> 46048 | JB1: =IR1+1 -> 46049 | JL1: =JB1+1 -> 46050 | JV1: =JL1+1 -> 46051 | KF1: =JV1+1 -> 46052 | KP1: =KF1+1 -> 46053
A2: Hora | B2: Tipo | C2: División | D2: Paciente | E2: Servicio | F2: Terapeuta | G2: Situación | H2: Consultorio | I2: $ / Pase | J2: Tipo pago | K2: Notas | L2: Tipo | M2: División | N2: Paciente | O2: Servicio | P2: Terapeuta | Q2: Situación | R2: Consultorio | S2: $ / Pase | T2: Tipo pago | U2: Notas | V2: Tipo | W2: División | X2: Paciente | Y2: Servicio | Z2: Terapeuta | AA2: Situación | AB2: Consultorio | AC2: $ / Pase | AD2: Tipo pago | AE2: Notas | AF2: Tipo | AG2: División | AH2: Paciente | AI2: Servicio | AJ2: Terapeuta | AK2: Situación | AL2: Consultorio | AM2: $ / Pase | AN2: Tipo pago | AO2: Notas | AP2: Tipo | AQ2: División | AR2: Paciente | AS2: Servicio | AT2: Terapeuta | AU2: Situación | AV2: Consultorio | AW2: $ / Pase | AX2: Tipo pago | AY2: Notas | AZ2: Tipo | BA2: División | BB2: Paciente | BC2: Servicio | BD2: Terapeuta | BE2: Situación | BF2: Consultorio | BG2: $ / Pase | BH2: Tipo pago | BI2: Notas | BJ2: Tipo | BK2: División | BL2: Paciente | BM2: Servicio | BN2: Terapeuta | BO2: Situación | BP2: Consultorio | BQ2: $ / Pase | BR2: Tipo pago | BS2: Notas | BT2: Tipo | BU2: División | BV2: Paciente | BW2: Servicio | BX2: Terapeuta | BY2: Situación | BZ2: Consultorio | CA2: $ / Pase | CB2: Tipo pago | CC2: Notas | CD2: Tipo | CE2: División | CF2: Paciente | CG2: Servicio | CH2: Terapeuta | CI2: Situación | CJ2: Consultorio | CK2: $ / Pase | CL2: Tipo pago | CM2: Notas | CN2: Tipo | CO2: División | CP2: Paciente | CQ2: Servicio | CR2: Terapeuta | CS2: Situación | CT2: Consultorio | CU2: $ / Pase | CV2: Tipo pago | CW2: Notas | CX2: Tipo | CY2: División | CZ2: Paciente | DA2: Servicio | DB2: Terapeuta | DC2: Situación | DD2: Consultorio | DE2: $ / Pase | DF2: Tipo pago | DG2: Notas | DH2: Tipo | DI2: División | DJ2: Paciente | DK2: Servicio | DL2: Terapeuta | DM2: Situación | DN2: Consultorio | DO2: $ / Pase | DP2: Tipo pago | DQ2: Notas | DR2: Tipo | DS2: División | DT2: Paciente | DU2: Servicio | DV2: Terapeuta | DW2: Situación | DX2: Consultorio | DY2: $ / Pase | DZ2: Tipo pago | EA2: Notas | EB2: Tipo | EC2: División | ED2: Paciente | EE2: Servicio | EF2: Terapeuta | EG2: Situación | EH2: Consultorio | EI2: $ / Pase | EJ2: Tipo pago | EK2: Notas | EL2: Tipo | EM2: División | EN2: Paciente | EO2: Servicio | EP2: Terapeuta | EQ2: Situación | ER2: Consultorio | ES2: $ / Pase | ET2: Tipo pago | EU2: Notas | EV2: Tipo | EW2: División | EX2: Paciente | EY2: Servicio | EZ2: Terapeuta | FA2: Situación | FB2: Consultorio | FC2: $ / Pase | FD2: Tipo pago | FE2: Notas | FF2: Tipo | FG2: División | FH2: Paciente | FI2: Servicio | FJ2: Terapeuta | FK2: Situación | FL2: Consultorio | FM2: $ / Pase | FN2: Tipo pago | FO2: Notas | FP2: Tipo | FQ2: División | FR2: Paciente | FS2: Servicio | FT2: Terapeuta | FU2: Situación | FV2: Consultorio | FW2: $ / Pase | FX2: Tipo pago | FY2: Notas | FZ2: Tipo | GA2: División | GB2: Paciente | GC2: Servicio | GD2: Terapeuta | GE2: Situación | GF2: Consultorio | GG2: $ / Pase | GH2: Tipo pago | GI2: Notas | GJ2: Tipo | GK2: División | GL2: Paciente | GM2: Servicio | GN2: Terapeuta | GO2: Situación | GP2: Consultorio | GQ2: $ / Pase | GR2: Tipo pago | GS2: Notas | GT2: Tipo | GU2: División | GV2: Paciente | GW2: Servicio | GX2: Terapeuta | GY2: Situación | GZ2: Consultorio | HA2: $ / Pase | HB2: Tipo pago | HC2: Notas | HD2: Tipo | HE2: División | HF2: Paciente | HG2: Servicio | HH2: Terapeuta | HI2: Situación | HJ2: Consultorio | HK2: $ / Pase | HL2: Tipo pago | HM2: Notas | HN2: Tipo | HO2: División | HP2: Paciente | HQ2: Servicio | HR2: Terapeuta | HS2: Situación | HT2: Consultorio | HU2: $ / Pase | HV2: Tipo pago | HW2: Notas | HX2: Tipo | HY2: División | HZ2: Paciente | IA2: Servicio | IB2: Terapeuta | IC2: Situación | ID2: Consultorio | IE2: $ / Pase | IF2: Tipo pago | IG2: Notas | IH2: Tipo | II2: División | IJ2: Paciente | IK2: Servicio | IL2: Terapeuta | IM2: Situación | IN2: Consultorio | IO2: $ / Pase | IP2: Tipo pago | IQ2: Notas | IR2: Tipo | IS2: División | IT2: Paciente | IU2: Servicio | IV2: Terapeuta | IW2: Situación | IX2: Consultorio | IY2: $ / Pase | IZ2: Tipo pago | JA2: Notas | JB2: Tipo | JC2: División | JD2: Paciente | JE2: Servicio | JF2: Terapeuta | JG2: Situación | JH2: Consultorio | JI2: $ / Pase | JJ2: Tipo pago | JK2: Notas | JL2: Tipo | JM2: División | JN2: Paciente | JO2: Servicio | JP2: Terapeuta | JQ2: Situación | JR2: Consultorio | JS2: $ / Pase | JT2: Tipo pago | JU2: Notas | JV2: Tipo | JW2: División | JX2: Paciente | JY2: Servicio | JZ2: Terapeuta | KA2: Situación | KB2: Consultorio | KC2: $ / Pase | KD2: Tipo pago | KE2: Notas | KF2: Tipo | KG2: División | KH2: Paciente | KI2: Servicio | KJ2: Terapeuta | KK2: Situación | KL2: Consultorio | KM2: $ / Pase | KN2: Tipo pago | KO2: Notas | KP2: Tipo | KQ2: División | KR2: Paciente | KS2: Servicio | KT2: Terapeuta | KU2: Situación | KV2: Consultorio | KW2: $ / Pase | KX2: Tipo pago | KY2: Notas
A3: 0.375 | AP3: S | AQ3: Particular | AS3: Evaluación neuropsicológica | AT3: Javier Martínez | AU3: Asistió | AV3: Guanajuato C3 | AW3: 350 | AX3: Tarjeta | BB3: AGENDAR LUCIA SANCHEZ SÓLO DE 9:00 A 10:00 | CP3: RENTA ESPACIO | CR3: Enrique Luna | CU3: 125 | DJ3: AGENDAR A LA LIC MARICELA A PARTIR DE LAS 3:00 | EC3: Particular | ED3: Alan Eduardo Mora Serrano | EE3: Individual 2025 | EF3: Maricela Sena | EG3: Reagendó | EH3: Guanajuato C1 | EI3: 420 | EK3: Dijo que mandaba mssj para volver a agendar prox. semana | FZ3: S | GA3: Particular | GB3: María Fernanda Rodríguez Daniel | GD3: Javier Martínez | GE3: Asistió | GF3: Guanajuato C3 | GG3: 350 | GH3: Tarjeta | GI3: Tiene costos autorizados por whats 350 con Lic. MArtínez y 150 con Lic Gloria | GJ3: S | GK3: Particular | GL3: Daniel Ramírez Cervantes | GM3: Individual | GN3: Maricela Sena | GO3: Asistió | GP3: Guanajuato C1 | GQ3: 420 | GR3: Efectivo | GS3: Pidio para 15 dias (6 enero) mismo dia misma hora | HF3: RENTA ESPACIO DR LUNA | HI3: Canceló | HX3: S | HY3: Particular | HZ3: Jorge Arturo Rodríguez Perales | IA3: Medica en salud mental | IB3: Javier Martínez | IC3: Asistió | ID3: Guanajuato C1 | IE3: $350 | IF3: Efectivo | IG3: Tiene estudio SE pero no está el papel físicamente | JN3: NO AGENDAR ESTE DIA AL DOC. ENRIQUE | KR3: BLOQUEADO LIC MARÍA AMANCIO | KU3: Confirmó
A4: 0.375 | AZ4: S | BA4: Particular | BB4: Daniel Ramírez | BC4: Individual | BD4: Maricela Sena | BE4: Asistió | BF4: Guanajuato C1 | BG4: 420 | BH4: Efectivo | BI4: su cita la quiere para dentro de 15 días
A5: 0.375 | BJ5: S | BK5: Particular | BL5: Alan Eduardo Mora Serrano | BM5: Individual 2025 | BN5: Maricela Sena | BO5: Asistió | BP5: Guanajuato C1 | BQ5: 420 | KP5: S | KQ5: Particular | KR5: Zaid Eliseo López | KS5: Infantil | KT5: Gloria Sarmiento | KU5: Confirmó | KV5: Guanajuato C3 | KW5: 500
A6: 0.375
A7: 0.41666667 | D7: Del 19 de Dic al 7de Enero, No agendar a Lic. Rosy | V7: N | W7: Particular | X7: Guadalupe Alejandra Aldaco Moya | Y7: Familiar | Z7: José Arcadio | AB7: Morelos C1 | AC7: 600 | AE7: Se presentó sin confirmar cita | AZ7: S | BA7: Particular | BB7: Alicia Minerva Ordóñez Hernandez | BC7: Individual 2025 | BD7: Maricela Sena | BE7: Asistió | BF7: Guanajuato C1 | BG7: $320 | BH7: Tarjeta | BL7: Del 19 de Dic al 7de Enero, No agendar a Lic. Rosy | BT7: S | BU7: GIASA | BV7: Juan Antonio Guerrero Ramírez | BW7: Individual 2025 | BX7: Maricela Sena | BY7: Asistió | BZ7: ZOOM C1 | CA7: 0 | CP7: RENTA ESPACIO | CR7: Enrique Luna | CU7: 125 | DH7: N | DI7: Particular | DJ7: Victor Manuel Agustince Rosales | DK7: Psicotanatología | DL7: Lucía Sánchez | DM7: No confirmó | DN7: Guanajuato C1 | DO7: 500 | DR7: S | DS7: Particular | DT7: Alicia Minerva Ordóñez Hernandez | DU7: Individual 2025 | DV7: Maricela Sena | DW7: Reagendó | DX7: Guanajuato C1 | DY7: $320 | EA7: Dijo que la prox semana se comunicaba para agendar a su mamá | EL7: S | EM7: GIASA | EN7: Juan Antonio Guerrero Ramírez | EO7: Individual 2025 | EP7: Maricela Sena | EQ7: Asistió | ER7: WhereBy 1 | ES7: 0 | ET7: Pase | EU7: Verificar si su siguiente cita será también por zoom o presencial | FF7: S | FG7: Particular | FH7: Monserrat Hernández | FI7: Individual 2025 | FJ7: Javier Martínez | FK7: Asistió | FL7: Guanajuato C1 | FM7: $420 | FN7: Tarjeta | HD7: S | HE7: GIASA | HF7: Juan Antonio Guerrero Ramírez | HG7: Individual 2025 | HH7: Maricela Sena | HI7: Reagendó | HJ7: WhereBy 1 | HK7: 0 | HL7: Pase | HM7: Reagendó para el sábado a las 6:00 presencial | HX7: S | HY7: Particular | HZ7: Luis Alberto Reyes Soto | IA7: Individual | IB7: José Arcadio | IC7: No confirmó | ID7: Morelos C1 | IE7: 420 | KP7: S | KQ7: Particular | KR7: Monserrat Hernández | KS7: Individual 2025 | KT7: Javier Martínez | KU7: Asistió | KV7: Guanajuato C1 | KW7: $420 | KX7: Efectivo
A8: 0.41666667 | V8: S | W8: Particular | X8: Monserrat Hernández | Y8: Individual 2025 | Z8: Javier Martínez | AA8: Asistió | AB8: Guanajuato C1 | AC8: $420 | AD8: Efectivo | BJ8: S | BK8: Particular | BL8: María Fernanda Medina y Hugo Torres | BM8: Pareja | BN8: Maria Amancio | BO8: No llegó | BP8: Guanajuato C1 | BQ8: 600 | BS8: 0.4375 | CN8: S | CO8: Particular | CP8: Genoveva Saucedo | CQ8: Individual | CR8: Javier Martínez | CS8: Reagendó | CT8: Guanajuato C3 | CU8: 420 | CV8: Efectivo | CW8: Ofrecerle cita con la lic Maria Amancio | FF8: N | FG8: Particular | FH8: Jhonatan Alexander de la Peña Sandate | FI8: Individual | FJ8: Daniela Sarmiento | FK8: Reagendó | FL8: Morelos C1 | FM8: 450 | FO8: Que el se comunicaba nuevamente | HX8: S | HY8: Particular | HZ8: Monserrat Hernández | IA8: Individual 2025 | IB8: Javier Martínez | IC8: Reagendó | ID8: Guanajuato C1 | IE8: $420 | KP8: N | KQ8: Particular | KR8: José Eduardo Sánchez Auces | KS8: Individual | KT8: José Arcadio | KU8: Asistió | KV8: Morelos C1 | KW8: 450 | KX8: Transf - 1872
A9: 0.41666667 | CN9: S | CO9: Particular | CP9: Luis Alberto Reyes Soto | CQ9: Individual | CR9: José Arcadio | CS9: Asistió | CT9: Morelos C1 | CU9: 420 | FF9: N | FG9: Particular | FH9: Guillermo Flores Dávila y Miriam Alejandra Argumedo García | FI9: Pareja | FJ9: Maria Amancio | FK9: Asistió | FL9: Guanajuato C2 | FM9: 600 | FN9: Tarjeta | FO9: Se les refirió por separado, Miriam ya tiene fecha el 24, dejó pendiente a Guillermo, con Arcadio | HX9: N | HY9: Particular | HZ9: Esteffani Magali Donias Alvarez | IA9: Individual | IB9: Gloria Sarmiento | IC9: Asistió | ID9: Guanajuato C2 | IE9: 675 | IF9: Tarjeta | IG9: No llegó a su cita pasada, se le avisó del 50% de multa, sobre el costo de cita de 450 | KP9: N | KQ9: Particular | KR9: Nayeli Abigail Santana Villanueva | KS9: Individual | KT9: Gloria Sarmiento | KU9: Canceló | KV9: Guanajuato C2 | KW9: 450
A10: 0.41666667
A11: 0.41666667
A12: 0.45833333 | L12: S | M12: Particular | N12: Juany Arellano | O12: Familiar | P12: David Bermejo | Q12: Por verificar | V12: N | W12: Particular | X12: Carmen Janeth Montiel Zavala, Carlos Roel Zuñiga Serrato | Y12: Pareja | Z12: José Arcadio | AA12: Asistió | AB12: Morelos C1 | AC12: 600 | AD12: Efectivo | AP12: S | AQ12: Particular | AR12: Sofía Alejandra Padilla Martínez | AS12: Individual 2025 | AT12: Lucía Sánchez | AU12: Asistió | AV12: Guanajuato C2 | AW12: $420 | AX12: Efectivo | AZ12: S | BA12: Particular | BB12: Beatriz Camarena | BC12: Individual 2025 | BD12: Maricela Sena | BE12: Asistió | BF12: Guanajuato C1 | BG12: 200 | BH12: Transf - 1872 | BT12: S | BU12: Particular | BV12: Emmanuel Jimenez Maqueda | BW12: Individual 2025 | BX12: Lucía Sánchez | BY12: Asistió | BZ12: Guanajuato C1 | CA12: 420 | CB12: Tarjeta | CP12: RENTA ESPACIO (Sandra Yazmin Salas Realista | CR12: Enrique Luna | CS12: Asistió | CU12: 125 | DR12: S | DS12: Particular | DT12: Fernanda Díaz Ortega | DU12: Individual 2025 | DV12: Maricela Sena | DW12: Confirmó | DX12: Guanajuato C1 | DY12: $350 | FH12: RENTA ESPACIO | FJ12: Enrique Luna | FK12: Confirmó | FZ12: S | GA12: Particular | GB12: Sofía Alejandra Padilla Martínez | GC12: Individual 2025 | GD12: Lucía Sánchez | GE12: Asistió | GF12: Guanajuato C2 | GG12: $420 | GH12: Transf - 1872 | GJ12: S | GK12: Particular | GL12: Alicia Minerva Ordóñez Hernandez | GM12: Individual | GN12: Maricela Sena | GO12: Asistió | GP12: Guanajuato C1 | GQ12: 320 | GS12: Terapeuta indicó citas una vez por semana | HD12: S | HE12: Particular | HF12: Emmanuel Jimenez Maqueda | HG12: Individual 2025 | HH12: Lucía Sánchez | HI12: Reagendó | HJ12: Guanajuato C1 | HK12: 420 | HM12: Le gusta Offenbach y La vie est belle | HX12: S | HY12: Particular | HZ12: Dora Luz Monsivais Martinez | IA12: Individual 2025 | IB12: José Arcadio | IC12: Incidente | ID12: Morelos C3 | IE12: $420 | IF12: Transf - 1872 | IG12: Confirmó cita desde otro contacto y luego no le tocaba hasta el prox sabado | JV12: S | JW12: Particular | JX12: Emmanuel Jimenez Maqueda | JY12: Individual 2025 | JZ12: Lucía Sánchez | KA12: Reagendó | KB12: Guanajuato C1 | KC12: 420
A13: 0.45833333 | Q13: No confirmó | CN13: N | CO13: Particular | CP13: Ana Sofía Zapata | CQ13: Infantil | CR13: Fabiola Fragoso | CS13: Asistió | CT13: Guanajuato C1 | CU13: 350 | CV13: Tarjeta | FF13: S | FG13: Particular | FH13: Carmen Janeth Montiel Zavala, Carlos Roel Zuñiga Serrato | FI13: Pareja | FJ13: José Arcadio | FK13: Canceló | FL13: Morelos C1 | FM13: 600 | FO13: Que ellos se volvían a comunicar | HX13: S | HY13: Particular | HZ13: Zaid Eliseo López | IA13: Infantil | IB13: Gloria Sarmiento | IC13: Asistió | ID13: Guanajuato C3 | IE13: 500 | IF13: Tarjeta | KP13: S | KQ13: Particular | KR13: Dora Luz Monsivais Martinez | KS13: Individual | KT13: José Arcadio | KU13: Asistió | KV13: Morelos C1 | KW13: 420 | KX13: Transf - 1872
A14: 0.45833333 | CN14: S | CO14: Particular | CP14: Dora Luz Monsiváis Martínez | CQ14: Individual 2025 | CR14: José Arcadio | CS14: Asistió | CT14: Morelos C3 | CU14: $420 | CV14: Transf - 1872 | FO14: Px quiso cambiar a virtual | KP14: S | KQ14: Particular | KR14: Dora Alicia Martinez | KS14: Individual 2025 | KT14: Enrique Luna | KU14: Asistió | KV14: Guanajuato C2 | KW14: 650 | KX14: Transf - 1872
A15: 0.45833333 | CN15: S | CO15: Particular | CP15: Valeria Monserrat López Mata | CQ15: Individual 2025 | CR15: Javier Martínez | CS15: Asistió | CT15: Guanajuato C1 | CU15: $420 | CV15: Tarjeta | FF15: N | FG15: Particular | FH15: Esteffani Magali Donias Alvarez | FI15: Individual | FJ15: Gloria Sarmiento | FK15: No llegó | FL15: Guanajuato C2 | FM15: $450 | FO15: No llegó, pidió reagendaro | HX15: S | HY15: Particular | HZ15: Isaías Hernández Lara | IA15: Médica psiquiatrica | IB15: Enrique Luna | IC15: Incidente | ID15: Guanajuato C1 | IE15: 850 | KP15: S | KQ15: Particular | KR15: Zaid Eliseo López | KS15: Infantil | KT15: Gloria Sarmiento | KU15: Asistió | KV15: Guanajuato C1 | KW15: 500 | KX15: Transf - 1872
A16: 0.45833333 | HZ16: RENTA ESPACIO ENRIQUE LUNA
A17: 0.5 | V17: S | W17: Particular | X17: Dora Luz Monsivais Martinez | Y17: Médica psiquiatrica | Z17: Enrique Luna | AA17: Asistió | AB17: Guanajuato C1 | AC17: 850 | AD17: Transf - 1872 | AP17: N | AQ17: Particular | AR17: Carlos Armando Coutiño Martinez | AS17: Individual | AT17: Lucía Sánchez | AU17: Asistió | AV17: Guanajuato C1 | AW17: $480 | AX17: Efectivo | AZ17: S | BA17: GIASA | BB17: Juan Antonio Guerrero Ramírez | BC17: Individual 2025 | BD17: Maricela Sena | BF17: ZOOM C1 | BG17: 0 | BH17: Pase | BI17: No se le mandó link ofrecerle otra fecha | BT17: N | BU17: Particular | BV17: Luis Carlos Reyes | BW17: Individual | BX17: Lucía Sánchez | BY17: Asistió | BZ17: ZOOM C1 | CA17: 450 | CB17: Transf - 1872 | CC17: De Louisiana | CN17: S | CO17: Particular | CP17: Fatima Valeria Nolasco | CQ17: Individual 2025 | CR17: Enrique Luna | CS17: Asistió | CT17: Guanajuato C1 | CU17: 510 | CV17: Efectivo | CW17: CUENTA CON ESTUDIO SE | EL17: S | EM17: Particular | EN17: Luis Carlos Reyes | EO17: Individual | EP17: Lucía Sánchez | EQ17: Asistió | ER17: WhereBy 1 | ES17: 450 | ET17: Transf - 1872 | FF17: S | FG17: Particular | FH17: Angel Mateo García González y Nicole García | FI17: Infantil | FJ17: Fabiola Fragoso | FK17: Asistió | FL17: Guanajuato C1 | FM17: 400 | FN17: Tarjeta | HD17: S | HE17: Particular | HF17: Luis Carlos Reyes | HG17: Individual | HH17: Lucía Sánchez | HI17: Asistió | HJ17: WhereBy 1 | HK17: 450 | HL17: Transf - 1872 | HM17: PAGADO | HX17: S | HY17: Particular | HZ17: Pedro Alejandro Herrera González | IA17: Individual 2025 | IB17: Enrique Luna | IC17: Asistió | ID17: Guanajuato C1 | IE17: 680 | IF17: Efectivo | IG17: Llamarle a la mamá, no tiene whatsapp | IT17: RENTA LIC GLORIA | IW17: Confirmó | IX17: Morelos C1 | IY17: 125 | JV17: S | JW17: Particular | JX17: Luis Carlos Reyes | JY17: Individual | JZ17: Lucía Sánchez | KA17: Asistió | KB17: WhereBy 1 | KC17: 450 | KD17: Transf - 1872 | KE17: PAGADO | KP17: S | KQ17: Particular | KR17: Yessica Anahí Rodriguez Palacios | KS17: Individual | KT17: José Arcadio | KU17: Reagendó | KV17: Morelos C1 | KW17: 420
A18: 0.5 | V18: N | W18: Particular | X18: Luis Alberto Reyes Soto | Y18: Individual | Z18: José Arcadio | AA18: Asistió | AB18: Morelos C1 | AC18: 420 | CN18: S | CO18: Particular | CP18: Cecilia Noriega Arévalo | CQ18: Individual 2025 | CR18: José Arcadio | CS18: Asistió | CT18: Morelos C3 | CU18: $400 | CV18: Efectivo | FF18: N | FG18: Particular | FH18: Valeria Bacio Hernández | FI18: Individual | FJ18: Gloria Sarmiento | FK18: Reagendó | FL18: Guanajuato C3 | FM18: $0 | FO18: Ya habia pagado y no se le dio cita, la proxima es de 225 | HX18: S | HY18: Particular | HZ18: Cecilia Noriega Arévalo | IA18: Individual 2025 | IB18: José Arcadio | IC18: Asistió | ID18: Morelos C3 | IE18: $400 | IF18: Transf - 1872 | IG18: COSTO POR ANTIGÜEDAD | KP18: S | KQ18: Particular | KR18: Isaías Hernández Lara | KS18: Medica en salud mental | KT18: Enrique Luna | KU18: Asistió | KV18: Guanajuato C1 | KW18: 850 | KX18: Tarjeta | KY18: PAGADO
A19: 0.5 | CN19: N | CO19: Particular | CP19: Valeria Bacio Hernández | CQ19: Individual | CR19: Benjamin Villagomez | CS19: Incidente | CT19: Guanajuato C2 | CU19: 450 | CV19: Transf - 1872 | CW19: FALTO LIC BENJAMIN | FF19: S | FG19: Particular | FH19: Celic Garcia | FI19: Individual | FJ19: Javier Martínez | FK19: Reagendó | FL19: Guanajuato C2 | FM19: 280 | FO19: Tiene estudio SE | HX19: N | HY19: Particular | HZ19: Valeria Bacio Hernández | IA19: Individual | IB19: Gloria Sarmiento | IC19: Canceló | ID19: Guanajuato C3 | IE19: 450 | IG19: PAGADO | KP19: S | KQ19: Particular | KR19: Pedro Alejandro González Herrera | KS19: Individual | KT19: Javier Martínez | KU19: Asistió | KV19: Guanajuato C2 | KW19: 350 | KX19: Efectivo
A20: 0.5
A21: 0.5
A22: 0.041666667 | V22: N | W22: Particular | X22: Claudia Martínez Duron | Y22: Individual | Z22: Enrique Luna | AA22: Reagendó | AB22: Guanajuato C1 | AD22: Transf - 1872 | AE22: Para el mierc 7 enero a las 5.00 pm | AP22: N | AQ22: Particular | AR22: Javier Bustamante Martinez | AS22: Individual | AT22: Lucía Sánchez | AU22: Asistió | AV22: Guanajuato C1 | AW22: 450 | AX22: Efectivo | CN22: S | CO22: Particular | CP22: Celic Garcia | CQ22: Médica psiquiatrica | CR22: Enrique Luna | CS22: Asistió | CT22: Guanajuato C1 | CU22: 640 | CV22: Transf - 1872 | DH22: N | DI22: Particular | DJ22: Zaid Eliseo López Bautista | DK22: Infantil | DL22: Gloria Sarmiento | DM22: Asistió | DN22: Morelos C1 | DO22: 500 | DP22: Efectivo | EL22: S | EM22: Particular | EN22: Carlos Armando Coutiño Martinez | EO22: Individual | EP22: Lucía Sánchez | EQ22: No llegó | ER22: Guanajuato C1 | ES22: $480 | FF22: S | FG22: Particular | FH22: Mario Zamarripa | FI22: Individual | FJ22: Javier Martínez | FK22: Asistió | FL22: WhereBy 1 | FM22: 420 | FN22: Transf - 1872 | FO22: Px quiso cambiar a virtual | HX22: S | HY22: Particular | HZ22: Miriam Alejandra Argumedo García | IA22: Individual | IB22: Maria Amancio | IC22: Asistió | ID22: Guanajuato C1 | IE22: 450 | IF22: Tarjeta | IG22: Vieme de Terapia de pareja, pasa a individual | IR22: N | IS22: Particular | IT22: Francisca Moreno (del Lic. Siller de Morelos) | IU22: Individual | IV22: Gloria Sarmiento | IW22: Asistió | IX22: Morelos C1 | IY22: $0 | JA22: Primer consulta de cortesía. Caso especial | KP22: R | KQ22: Particular | KR22: María Fernanda Rodríguez Daniel | KS22: Familiar | KT22: José Arcadio | KU22: Canceló | KV22: Morelos C1 | KW22: 400 | KY22: COSTOS AUTORIZADOS: 150 Gloria, 350 Lic Mrtínez, 400 Familar Arcadio
A23: 0.041666667 | X23: Renta espacio (1:30 llegó) | Z23: Enrique Luna | AC23: 125 | AD23: Efectivo | AE23: Pagado | FF23: S | FG23: Particular | FH23: Yessica Anahí Rodriguez Palacios | FI23: Medica en salud mental | FJ23: Enrique Luna | FK23: Asistió | FL23: Guanajuato C3 | FM23: 680 | FN23: Transf - 1872 | FO23: PAGADO | HX23: S | HY23: Particular | HZ23: Juan Diego López Balderas | IA23: Individual 2025 | IB23: Benjamin Villagomez | IC23: Asistió | ID23: Guanajuato C2 | IE23: 380 | IF23: Tarjeta | IG23: 0.5625 | KP23: S | KQ23: Particular | KR23: Rocio Karina Mesquitic Mendoza | KS23: Medica en salud mental | KT23: Enrique Luna | KU23: Asistió | KV23: Guanajuato C1 | KW23: 850 | KX23: Transf - 1872
A24: 0.041666667 | KP24: S | KQ24: Particular | KR24: Ana Sofía Zapata | KS24: Infantil | KT24: Fabiola Fragoso | KU24: Asistió | KV24: Guanajuato C1 | KW24: 350 | KX24: Transf - 1872 | KY24: LA movió la terapeuta de las 11 a la 1
A25: 0.041666667
A26: 0.041666667
A27: 0.083333333 | V27: S | W27: NEAPCO | X27: Joksan Ishbak Cruz Torres | Y27: Individual 2025 | Z27: Daniela Sarmiento | AA27: Asistió | AB27: Morelos C2 | AC27: 0 | AD27: Pase | AZ27: N | BA27: Particular | BB27: Cecilia Lourdes González Carranza | BC27: Individual | BD27: Gloria Sarmiento | BE27: No llegó | BF27: Morelos C1 | BG27: 450 | BT27: N | BU27: NEAPCO | BV27: Karina Segovia Ramírez | BW27: Individual | BX27: Gloria Sarmiento | BY27: Asistió | BZ27: Morelos C1 | CA27: 0 | CB27: Pase | CC27: Es la mamá de la paciente | EL27: S | EM27: Particular | EN27: Daniela Huerta Ovalle | EO27: Individual 2025 | EP27: María de la Luz | EQ27: Asistió | ER27: Guanajuato C1 | ES27: 350 | ET27: Tarjeta | FZ27: N | GA27: Particular | GB27: Sofía Marinette Segura Viera | GC27: Infantil | GD27: Gloria Sarmiento | GE27: Asistió | GF27: Morelos C1 | GG27: 500 | GH27: Efectivo | HD27: S | HE27: Particular | HF27: Daniela Huerta Ovalle | HG27: Individual 2025 | HH27: María de la Luz | HI27: Incidente | HJ27: Guanajuato C1 | HK27: 350 | HM27: Canceló la Terapeuta | HN27: S | HO27: NEAPCO | HP27: Karina Segovia Ramírez (su mamá es la paciente) | HQ27: Individual | HR27: Gloria Sarmiento | HS27: Asistió | HT27: Morelos C1 | HU27: 0 | HV27: Pase | HX27: S | HY27: NEAPCO | HZ27: Derek Daniel Salas | IA27: Individual | IB27: Daniela Sarmiento | IC27: Confirmó | ID27: WhereBy 1 | IE27: 0 | IF27: Pase | IR27: S | IS27: Particular | IT27: Sofía Marinette Segura Viera | IU27: Infantil | IV27: Gloria Sarmiento | IW27: Asistió | IX27: Morelos C1 | IY27: 500 | IZ27: Efectivo | JL27: S | JM27: Particular | JN27: Rodrigo Alejandro Vázquez Cázares | JO27: Individual | JP27: Gloria Sarmiento | JQ27: Asistió | JR27: Morelos C1 | JS27: 675 | JT27: Transf - 1872 | JU27: Faltó a su anterior cita, el que se presentó fue su hermano Ángel Jaziel | JV27: S | JW27: Particular | JX27: Daniela Huerta Ovalle | JY27: Individual 2025 | JZ27: María de la Luz | KA27: Asistió | KB27: Guanajuato C1 | KC27: 350 | KD27: Tarjeta | KF27: S | KG27: NEAPCO | KH27: Karina Segovia Ramírez (mamá) | KI27: Individual | KJ27: Gloria Sarmiento | KK27: Confirmó | KL27: Morelos C1 | KM27: 0 | KN27: Pase | KP27: N | KQ27: Particular | KR27: María Cristina Domínguez | KS27: Individual | KT27: Daniela Sarmiento | KU27: No confirmó | KV27: Morelos C2 | KW27: 450 | KY27: PASAR SINTOMAS A LA LIC DANIEL
A28: 0.083333333 | BJ28: S | BK28: Particular | BL28: Carlos Joel Santos Nuncio | BM28: Individual | BN28: Gloria Sarmiento | BO28: Asistió | BP28: Morelos C1 | BQ28: 420 | BR28: Efectivo | BT28: S | BU28: Particular | BV28: Daniela Huerta Ovalle | BW28: Individual 2025 | BX28: María de la Luz | BY28: Asistió | BZ28: Guanajuato C1 | CA28: 0 | CB28: Gratuito | EL28: N | EM28: NEAPCO | EN28: Karina Segovia Ramírez (su mamá es la paciente) | EO28: Individual | EP28: Gloria Sarmiento | EQ28: Asistió | ER28: Morelos C1 | ES28: 0 | ET28: Pase | EU28: Preguntar si la mama puede usar el pase de empleada de neapco | JV28: N | JW28: INSUNTE | JX28: Alondra Marisol García Medina | JY28: Individual | JZ28: Lucía Sánchez | KA28: Asistió | KB28: Guanajuato C2 | KC28: 300 | KD28: Efectivo | KR28: TENTATIVO KARINA PARA LIC FABIOLA
A29: 0.083333333 | CN29: N | CO29: Particular | CP29: Daniela Rafael Sifuentes | CQ29: Individual | CR29: Benjamin Villagomez | CS29: Confirmó | CT29: Guanajuato C1 | CU29: 450 | JV29: S | JW29: Particular | JX29: Carlos Arturo García Limón | JY29: Individual | JZ29: Gloria Sarmiento | KA29: Asistió | KB29: Morelos C1 | KC29: 340 | KD29: Efectivo
A30: 0.083333333
A31: 0.083333333
A32: 0.125 | V32: S | W32: Particular | X32: Isaías Hernández Lara | Y32: Individual 2025 | Z32: Daniela Sarmiento | AA32: Asistió | AB32: Morelos C1 | AC32: $420 | AD32: Efectivo | AE32: Se hizo 50% descuento ($210) | AP32: S | AQ32: Particular | AR32: Ricardo Guadalupe López Ramos | AS32: Individual 2025 | AT32: Lucía Sánchez | AU32: Asistió | AV32: Guanajuato C2 | AW32: 420 | AX32: Tarjeta | AZ32: S | BA32: INSUNTE | BB32: Alan Mitsael Flores Vazquez | BC32: Individual 2025 | BD32: Maricela Sena | BE32: Reagendó | BF32: Guanajuato C1 | BG32: 300 | BI32: Para el viernes 9 enero a las 3:00 | BJ32: S | BK32: Particular | BL32: Eva Isabel Valerdi Cortés | BM32: Infantil | BN32: Gloria Sarmiento | BO32: Asistió | BP32: Morelos C2 | BQ32: 360 | BR32: Efectivo | CD32: S | CE32: INSUNTE | CF32: Alan Mitsael Flores Vazquez | CG32: Individual | CH32: Maricela Sena | CI32: Asistió | CJ32: Guanajuato C1 | CK32: 300 | CL32: Tarjeta | CN32: N | CO32: Particular | CP32: Isabella Jocelin Borja Sifuentes | CQ32: Infantil | CR32: Fabiola Fragoso | CT32: Guanajuato C2 | CU32: 420 | EL32: S | EM32: Particular | EN32: Carlos Arturo García Limón | EO32: Individual | EP32: Gloria Sarmiento | EQ32: Asistió | ER32: Morelos C1 | ES32: 420 | ET32: Efectivo | EU32: Dice en la bitácora que él mandará mensaje nuevamente | FF32: S | FG32: Particular | FH32: Isaías Hernández Lara | FI32: Individual 2025 | FJ32: Daniela Sarmiento | FL32: WhereBy 1 | FM32: $420 | FN32: Transf - 1872 | FO32: PAGADO canceló por enfermedad | FZ32: S | GA32: Particular | GB32: Ricardo Guadalupe López Ramos | GC32: Individual 2025 | GD32: Lucía Sánchez | GE32: Asistió | GF32: Guanajuato C2 | GG32: 420 | GH32: Tarjeta | GT32: S | GU32: Particular | GV32: Eva Isabel Valerdi Cortés | GW32: Infantil | GX32: Gloria Sarmiento | GY32: Reagendó | GZ32: Morelos C2 | HA32: 300 | HC32: PARA MIERC 28 ENERO POR ENFERMEDAD DE LA NIÑA | HN32: S | HO32: Particular | HP32: Fernanda Diaz Ortega | HQ32: Individual | HR32: Maricela Sena | HS32: Asistió | HT32: Guanajuato C1 | HU32: 350 | HV32: Tarjeta | HX32: S | HY32: Particular | HZ32: Dora Alicia Martinez | IA32: Individual 2025 | IB32: Javier Martínez | ID32: Guanajuato C2 | IE32: 0 | IF32: Gratuito | IG32: PENDIENTE PASAR HORARIO | IR32: S | IS32: GIASA | IT32: Marco Antonio Hinojosa Hernández | IU32: Individual | IV32: Maricela Sena | IW32: No llegó | IX32: Guanajuato C1 | IY32: 0 | IZ32: Pase | JB32: S | JC32: NEAPCO | JD32: Fe Garay | JE32: Individual | JF32: Gloria Sarmiento | JG32: Asistió | JH32: Morelos C1 | JJ32: Pase | JL32: S | JM32: Particular | JN32: Eva Isabel Valerdi Cortés | JO32: Infantil | JP32: Gloria Sarmiento | JQ32: Asistió | JR32: Morelos C1 | JS32: 300 | JT32: Efectivo | JU32: PARA MIERC 28 ENERO POR ENFERMEDAD DE LA NIÑA | KH32: RENTA ALISSON BERMAN | KJ32: Alisson Berman | KK32: Confirmó | KL32: Guanajuato C1 | KM32: 125 | KP32: S | KQ32: Particular | KR32: Isaías Hernández Lara | KS32: Individual 2025 | KT32: Daniela Sarmiento | KU32: Asistió | KV32: Morelos C1 | KW32: $420 | KX32: Transf - 1872 | KY32: PAGADO canceló por enfermedad la lic la cita pasada
A33: 0.125 | V33: N | W33: Particular | X33: Mario Alberto Martinez Lozano | Y33: Individual | Z33: Enrique Luna | AA33: No llegó | AB33: Guanajuato C1 | AC33: 850 | CD33: S | CE33: NEAPCO | CF33: Fe Garay | CG33: Individual 2025 | CH33: Gloria Sarmiento | CI33: Asistió | CJ33: Morelos C1 | CK33: 0 | CL33: Pase | CN33: S | CO33: Particular | CP33: Samuel y Adin Valles | CQ33: Familiar | CR33: Daniela Sarmiento | CS33: Confirmó | CT33: Morelos C1 | CU33: 550 | EV33: S | EW33: NEAPCO | EX33: Fe Garay | EY33: Individual 2025 | EZ33: Gloria Sarmiento | FA33: No confirmó | FB33: Morelos C1 | FC33: 0 | FD33: Pase | FE33: Dice en bitácora que ellá volverá a mandar mensaje | FF33: S | FG33: Particular | FH33: Valeria Janeth Márquez Muñiz | FI33: Medica en salud mental | FJ33: Enrique Luna | FK33: Asistió | FL33: Guanajuato C1 | FM33: 850 | FN33: Transf - 1872 | FO33: Cambio de hora ,"que sea seguro" dice Px. | HX33: N | HY33: Particular | HZ33: José Francisco Rodríguez Pérez | IA33: Individual | IB33: Daniela Sarmiento | IC33: Incidente | ID33: Morelos C1 | IE33: 450 | IG33: ENVIAR ANTECEDENTE QUE MANDÓ LA PX | KF33: S | KG33: Particular | KH33: Fernanda Diaz Ortega | KI33: Individual | KJ33: Maricela Sena | KL33: Guanajuato C1 | KM33: 350 | KO33: AGENDÓ EN ESCRITORIO DE RECEPCIÓN ALICIA PARA LAS DOS 13 DE FEB y ALICIA CON DR 14 FEB | KR33: RENTA ESPACIO DR LUNA | KT33: Enrique Luna | KU33: Confirmó | KV33: Guanajuato C1
A34: 0.125 | CP34: RENTA DE ESPACIO | CR34: Enrique Luna | CS34: Confirmó | CU34: 125 | CW34: PROBABLE CHRISTIAN BARRIOS
A35: 0.125
A36: 0.125
A37: 0.16666667 | L37: N | M37: Particular | N37: Nayelli Monserrat Reyna De Leon | O37: Individual | P37: Gloria Sarmiento | Q37: Asistió | R37: Morelos C1 | S37: 450 | T37: Efectivo | V37: S | W37: NEAPCO | X37: Derek Daniel Salas | Y37: Individual | Z37: Daniela Sarmiento | AA37: Asistió | AB37: Morelos C1 | AC37: 0 | AD37: Pase | AP37: S | AQ37: Particular | AR37: Anayansi Rincón Patiño | AS37: Individual | AT37: Javier Martínez | AU37: Asistió | AV37: Guanajuato C1 | AW37: 420 | AX37: Efectivo | BJ37: S | BK37: Particular | BL37: Ana Sofia Zapata | BM37: Consulta psiquiatrica | BN37: Enrique Luna | BO37: Asistió | BP37: Guanajuato C1 | BQ37: 700 | BR37: Tarjeta | BT37: S | BU37: Particular | BV37: Jonas Alejandro Morales | BW37: Individual 2025 | BX37: José Arcadio | BY37: Confirmó | BZ37: ZOOM C1 | CA37: $420 | CD37: S | CE37: Particular | CF37: Cristian Gómez | CG37: Individual 2025 | CH37: Maricela Sena | CI37: No confirmó | CJ37: Guanajuato C1 | CK37: 420 | CN37: N | CO37: Particular | CP37: Jhonatan Alexander de la Peña Sandate | CQ37: Individual | CR37: Daniela Sarmiento | CS37: No llegó | CT37: Morelos C1 | CU37: 450 | CV37: Transf - 1872 | DH37: N | DI37: Particular | DJ37: Maria Fernanda Rodriguez Daniel | DL37: Gloria Sarmiento | DM37: Asistió | DN37: Morelos C1 | DO37: 150 | DP37: Efectivo | DQ37: Tiene costos autorizados por whatsapp | EB37: S | EC37: Particular | ED37: Devany Alejandra Acosta Reyes | EE37: Consulta psiquiatrica | EF37: Enrique Luna | EG37: Asistió | EH37: Guanajuato C1 | EI37: 850 | EJ37: Efectivo | EL37: S | EM37: Particular | EN37: Jorge Arturo Rodríguez Perales | EO37: Medica en salud mental | EP37: Enrique Luna | EQ37: Confirmó | ER37: Guanajuato C1 | ES37: $680 | EU37: Recuperación | EV37: N | EW37: Particular | EX37: Angelica Berenice Dogart Urbina | EY37: Individual | EZ37: Maricela Sena | FA37: No confirmó | FB37: Guanajuato C1 | FC37: 450 | FF37: S | FG37: NEAPCO | FH37: Derek Daniel Salas | FI37: Individual | FJ37: Daniela Sarmiento | FK37: Incidente | FL37: WhereBy 1 | FM37: 0 | FN37: Pase | FO37: Se enfermó la Lic Daniela, reagenda Px para el sig. sabado virtual | FZ37: N | GA37: Particular | GB37: Ángel Gaciel Vázquez Cázares | GC37: Individual | GD37: Gloria Sarmiento | GE37: Asistió | GF37: Morelos C1 | GG37: 450 | GH37: Efectivo | GI37: MAndar confirmacion 8444941798 | GJ37: N | GK37: Particular | GL37: Dante Jaziel Armas de la Peña | GM37: Infantil | GN37: Gloria Sarmiento | GO37: Asistió | GP37: Morelos C2 | GQ37: $460 | GR37: Efectivo | GS37: paga 460 porque se le debieron 20 de cambio | GT37: S | GU37: Particular | GV37: Devany Alejandra Acosta Reyes | GW37: Individual | GX37: Lucía Sánchez | GY37: Asistió | GZ37: Guanajuato C1 | HA37: 420 | HB37: Efectivo | HC37: Me lo pasó por whats Valery | HN37: S | HO37: INSUNTE | HP37: Alan Mitsael Flores Vazquez | HQ37: Individual | HR37: Maricela Sena | HS37: Asistió | HT37: Guanajuato C1 | HU37: 300 | HV37: Tarjeta | HX37: N | HY37: Particular | HZ37: María Fernanda García Rodríguez y Carlos Aurelio Duarte Trejo | IA37: Pareja | IB37: Daniela Sarmiento | IC37: Confirmó | ID37: Morelos C1 | IE37: 600 | IR37: S | IS37: Particular | IT37: Ángel Jaciel Vázquez Cázares | IU37: Individual | IV37: Gloria Sarmiento | IW37: Asistió | IX37: Morelos C1 | IY37: 450 | IZ37: Transf - 1872 | JA37: MAndar confirmacion 8444941798 | JB37: S | JC37: Particular | JD37: Dante Jaziel Armas de la Peña | JE37: Infantil | JF37: Gloria Sarmiento | JG37: Asistió | JH37: Morelos C2 | JI37: 480 | JK37: PENDIENTE COMPROBANTE PAGO | JL37: S | JM37: Particular | JN37: María de la Luz Ruiz Armendáriz | JO37: Individual | JP37: Lucía Sánchez | JQ37: Asistió | JR37: Guanajuato C1 | JS37: 450 | JT37: Transf - 1872 | JV37: N | JW37: Dorothea | JX37: Melissa Estefanía Gonzalez Ortiz | JY37: Individual | JZ37: Gloria Sarmiento | KA37: No confirmó | KB37: Morelos C1 | KC37: 350 | KF37: S | KG37: INSUNTE | KH37: Alan Mitsael Flores Vazquez | KI37: Individual | KJ37: Maricela Sena | KK37: Asistió | KL37: Guanajuato C1 | KM37: 300 | KN37: Transf - 1872 | KP37: S | KQ37: NEAPCO | KR37: Derek Daniel Salas | KS37: Individual | KT37: Daniela Sarmiento | KU37: Asistió | KV37: WhereBy 1 | KW37: 0 | KX37: Pase
A38: 0.16666667 | BJ38: S | BK38: Particular | BL38: María de Lourdes Martinez Reyna | BM38: Individual 2025 | BN38: Rosy Macias | BP38: Morelos C1 | BQ38: 350 | BR38: Efectivo | BS38: Se omitió día que no iba a laborar la terapeuta y se agendó a paciente | BT38: S | BU38: Particular | BV38: Frida Sofía Sánchez Sánchez | BW38: Individual | BX38: Lucía Sánchez | BZ38: Guanajuato C1 | CA38: 420 | CD38: N | CE38: Particular | CF38: Juan Antonio Izquierdo Treviño | CG38: Individual | CH38: Maricela Sena | CI38: Asistió | CJ38: Guanajuato C1 | CK38: 450 | CL38: Efectivo | CN38: S | CO38: NEAPCO | CP38: Julio Alejandro Moreno Moncada | CQ38: Médica psiquiatrica | CR38: Enrique Luna | CS38: Confirmó | CT38: Guanajuato C1 | CU38: 0 | CV38: Pase | DR38: N | DS38: Particular | DT38: Dante Jaziel Armas de la Peña | DU38: Infantil | DV38: Gloria Sarmiento | DW38: Asistió | DX38: Morelos C2 | DY38: 480 | DZ38: Efectivo | EA38: Nuevo ingreso; se respetó costo que vio en publicación | EB38: N | EC38: Particular | ED38: María de la Luz Ruiz Armendáriz | EE38: Individual | EF38: Lucía Sánchez | EG38: Asistió | EH38: Guanajuato C2 | EI38: 450 | EJ38: Transf - 1872 | EK38: PAGADO | EL38: S | EM38: Particular | EN38: Eva Isabel Valerdi Cortés | EO38: Infantil | EP38: Gloria Sarmiento | EQ38: Asistió | ER38: Morelos C2 | ES38: 300 | ET38: Efectivo | EU38: Canceló mierc 13 Lic por contratiempo/ Autorizan estudio SE | FF38: S | FG38: Particular | FH38: Luis Alberto Reyes Soto | FI38: Medica en salud mental | FJ38: Enrique Luna | FK38: Canceló | FL38: Guanajuato C1 | FM38: 850 | GT38: S | GU38: Particular | GV38: Vivían Yoselin Valdez Sifuentes | GW38: Individual | GX38: Gloria Sarmiento | GY38: Asistió | GZ38: Morelos C1 | HA38: 300 | HC38: Referida de la Fundación Érika/ La lic canceló el 13 por contratiempo | HN38: S | HO38: Particular | HP38: Carlos Arturo García Limón | HQ38: Individual | HR38: Gloria Sarmiento | HS38: Asistió | HT38: Morelos C1 | HU38: 340 | HV38: Transf - 1872 | HW38: REVISAR COSTO | HZ38: RENTA ESPACIO ALISSON BERMEA | IC38: Confirmó | ID38: Guanajuato C1 | IE38: 125 | JB38: S | JC38: Particular | JD38: Dora Alicia Martinez Juarez | JE38: Individual | JF38: Javier Martínez | JG38: Confirmó | JH38: Guanajuato C1 | JI38: 0 | JJ38: Pase | JL38: N | JM38: Particular | JN38: Raymundo Damian Tovar García | JO38: Infantil | JP38: Gloria Sarmiento | JQ38: Reagendó | JR38: Morelos C1 | JS38: 500 | KF38: N | KG38: Particular | KH38: María Teresa Agin Hernández | KI38: Individual | KJ38: Lucía Sánchez | KK38: No confirmó | KL38: Guanajuato C2 | KM38: 450 | KR38: RENTA ESPACIO LIC ALISSON BERMAN | KT38: Alisson Berman | KU38: Confirmó | KV38: Guanajuato C1
A39: 0.16666667 | BJ39: S | BK39: Particular | BL39: Alberto de Jesús Ramos Barrientos | BM39: Individual 2025 | BN39: Gloria Sarmiento | BO39: Confirmó | BP39: Morelos C2 | BQ39: 340 | BT39: S | BU39: Particular | BV39: Maria de Lourdes Martínez | BW39: Individual | BX39: Rosy Macias | BY39: Asistió | BZ39: Morelos C1 | CA39: 350 | CB39: Transf - 1872 | JL39: S | JM39: Fundación Erika | JN39: Vivían Yoselin Valdez Sifuentes | JO39: Individual | JP39: Gloria Sarmiento | JQ39: No confirmó | JR39: Morelos C1 | JS39: 300
A40: 0.16666667 | BJ40: S | BK40: Particular | BL40: Devany Alejandra Acosta Reyes | BM40: Individual | BN40: Lucía Sánchez | BO40: Reagendó | BP40: Guanajuato C2 | BQ40: 420 | BS40: Para el 21 de enero a las 4 | BV40: RENTA DE ESPACIO | BX40: Maria Amancio | BZ40: Guanajuato C2 | CA40: 125
...

Sheet Nov 25
B1: 45962 | L1: =B1+1 -> 45963 | V1: =L1+1 -> 45964 | AF1: =V1+1 -> 45965 | AP1: =AF1+1 -> 45966 | AZ1: =AP1+1 -> 45967 | BJ1: =AZ1+1 -> 45968 | BT1: =BJ1+1 -> 45969 | CD1: =BT1+1 -> 45970 | CN1: =CD1+1 -> 45971 | CX1: =CN1+1 -> 45972 | DH1: =CX1+1 -> 45973 | DR1: =DH1+1 -> 45974 | EB1: =DR1+1 -> 45975 | EL1: =EB1+1 -> 45976 | EV1: =EL1+1 -> 45977 | FF1: =EV1+1 -> 45978 | FP1: =FF1+1 -> 45979 | FZ1: =FP1+1 -> 45980 | GJ1: =FZ1+1 -> 45981 | GT1: =GJ1+1 -> 45982 | HD1: =GT1+1 -> 45983 | HN1: =HD1+1 -> 45984 | HX1: =HN1+1 -> 45985 | IH1: =HX1+1 -> 45986 | IR1: =IH1+1 -> 45987 | JB1: =IR1+1 -> 45988 | JL1: =JB1+1 -> 45989 | JV1: =JL1+1 -> 45990 | KF1: =JV1+1 -> 45991
