Workbook

Sheet DISRA
A1: ID|number-2 | B1: Nombre completo|name-1 | C1: Sexo|select-1 | D1: Estado Civil|select-2 | E1: Edad|number-1 | F1: Fecha de nacimiento|date-1 | G1: Fecha de realización de la encuesta|date-2 | H1: Introduzca la hora y minuto en que comenzó la encuesta|time-1 | I1: 1.-Ante un examen en el que me juego mucho, o si voy a ser entrevistado para un trabajo importante, me preocupo facilmente.|radio-1 | J1: 2.-Ante un examen en el que me juego mucho, o si voy a ser entrevistado para un trabajo importante, me cuesta concentrarme.|radio-2 | K1: 3.-Cuando voy a llegar tarde a una cita, me preocupo facilmente.|radio-3 | L1: 4.-Cuando pienso en las muchas cosas que tengo que hacer doy demasiadas vueltas a las cosas sin llegar a decidirme.|radio-4 | M1: 5.-Cuando pienso en las muchas cosas que tengo que hacer me cuesta concentrarme.|radio-5 | N1: 6.-A la hora de tomar una decisión o resolver un problema difícil me preocupo facilmente.|radio-6 | O1: 7.-A la hora de tomar una decisión o resolver un problema difícil me cuesta concentrarme.|radio-7 | P1: 8.-En mi trabajo o cuando estudio me siento inseguro de mí mismo.|radio-8 | Q1: 9.-En mi trabajo o cuando estudio doy demasiadas vueltas a las cosas sin llegar a decidirme.|radio-9 | R1: 10.-Cuando espero a alguien en un lugar un concurrido me preocupo facilmente.|radio-10 | S1: 11.-Cuando espero a alguien en un lugar un concurrido tengo pensamientos o sentimientos negativos sobre mí, tales como "inferior" a los demás, "torpe", etc|radio-11 | T1: 12.-Cuando espero a alguien en un lugar un concurrido doy demasiadas vueltas a las cosas sin llegar a decidirme.|radio-12 | U1: 13.-Cuando espero a alguien en un lugar un concurrido pienso que la gente se dará cuenta de mis problemas o de la torpeza de mis actos.|radio-13 | V1: 14.-Si una persona del otro sexo está muy cerca de mí, rozándome , o si estoy en una situación sexual íntima doy demasiadas vueltas a las cosas sin llegar a decidirme.|radio-14 | W1: 15.-Cuando alguien me molesta o cuando discuto tengo pensamientos o sentimientos negativos sobre mí, tales como "inferior" a los demás, "torpe", etc|radio-15 | X1: 16.-Cuando alguien me molesta o cuando discuto pienso que la gente se dará cuenta de mis problemas o de la torpeza de mis actos.|radio-16 | Y1: 17.-Cuando soy observado o mi trabajo es supervisado, cuando recibo críticas, o siempre que pueda ser evaluado negativamente me cuesta concentrarme.|radio-17 | Z1: 18.-Cuando soy observado o mi trabajo es supervisado, cuando recibo críticas, o siempre que pueda ser evaluado negativamente pienso que la gente se dará cuenta de mis problemas o de la torpeza de mis actos.|radio-18 | AA1: 19.-Si tengo que hablar en público me preocupo facilmente.|radio-19 | AB1: 20.-Si tengo que hablar en público doy demasiadas vueltas a las cosas sin llegar a decidirme.|radio-20 | AC1: 21.-Si tengo que hablar en público me cuesta concentrarme.|radio-21 | AD1: 22.-Si tengo que hablar en público pienso que la gente se dará cuenta de mis problemas o de la torpeza de mis actos.|radio-22 | AE1: 23.-Cuando pienso en experiencias recientes en las que me he sentido ridículo, tímido, humillado, solo o rechazado me cuesta concentrarme.|radio-23 | AF1: 24.-Cuando tengo que viajar en avión o en barco me siento inseguro de mí mismo.|radio-24 | AG1: 25.-Cuando tengo que viajar en avión o en barco siento miedo.|radio-25 | AH1: 26.-Cuando tengo que viajar en avión o en barco me cuesta concentrarme.|radio-26 | AI1: 27.-Después de haber cometido algún error doy demasiadas vueltas a las cosas sin llegar a decidirme.|radio-27 | AJ1: 28.-Después de haber cometido algún error siento miedo.|radio-28 | AK1: 29.-Después de haber cometido algún error me cuesta concentrarme.|radio-29 | AL1: 30.-Después de haber cometido algún error pienso que la gente se dará cuenta de mis problemas o de la torpeza de mis actos.|radio-30 | AM1: 31.-Ante la consulta del dentista, las inyecciones, las heridas o la sangre me preocupo facilmente.|radio-31 | AN1: 32.-Cuando voy a una cita con una persona del otro sexo siento miedo.|radio-32 | AO1: 33.-Cuando pienso en mi futuro o en dificultades y problemas futuros me cuesta concentrarme.|radio-33 | AP1: 34.-En medio de multitudes o en espacios cerrados me preocupo facilmente.|radio-34 | AQ1: 35.-En medio de multitudes o en espacios cerrados tengo pensamientos o sentimientos negativos sobre mí, tales como "inferior" a los demás, "torpe", etc|radio-35 | AR1: 36.-En medio de multitudes o en espacios cerrados siento miedo.|radio-36 | AS1: 37.-En medio de multitudes o en espacios cerrados me cuesta concentrarme.|radio-37 | AT1: 38.-En medio de multitudes o en espacios cerrados pienso que la gente se dará cuenta de mis problemas o de la torpeza de mis actos.|radio-38 | AU1: 39.-Cuando tengo que asistir a una reunión social o conocer gente nueva me siento inseguro de mí mismo.|radio-39 | AV1: 40.-Cuando tengo que asistir a una reunión social o conocer gente nueva me cuesta concentrarme.|radio-40 | AW1: 41.-En lugares altos, o ante aguas profundas me preocupo facilmente.|radio-41 | AX1: 42.-En lugares altos, o ante aguas profundas tengo pensamientos o sentimientos negativos sobre mí, tales como "inferior" a los demás, "torpe", etc|radio-42 | AY1: 43.-En lugares altos, o ante aguas profundas me siento inseguro de mí mismo.|radio-43 | AZ1: 44.-En lugares altos, o ante aguas profundas siento miedo.|radio-44 | BA1: 45.-En lugares altos, o ante aguas profundas pienso que la gente se dará cuenta de mis problemas o de la torpeza de mis actos.|radio-45 | BB1: 46.-Al observar escenas violentas me preocupo facilmente.|radio-46 | BC1: 47.-Al observar escenas violentas tengo pensamientos o sentimientos negativos sobre mí, tales como "inferior" a los demás, "torpe", etc|radio-47 | BD1: 48.-Al observar escenas violentas siento miedo.|radio-48 | BE1: 49.-Por nada en concreto me preocupo facilmente.|radio-49 | BF1: 50.-Por nada en concreto tengo pensamientos o sentimientos negativos sobre mí, tales como "inferior" a los demás, "torpe", etc|radio-50 | BG1: 51.-Por nada en concreto me siento inseguro de mí mismo.|radio-51 | BH1: 52.-Por nada en concreto doy demasiadas vueltas a las cosas sin llegar a decidirme.|radio-52 | BI1: 53.-Por nada en concreto siento miedo.|radio-53 | BJ1: 54.-A la hora de dormir me preocupo facilmente.|radio-54 | BK1: 55.-A la hora de dormir tengo pensamientos o sentimientos negativos sobre mí, tales como "inferior" a los demás, "torpe", etc|radio-55 | BL1: 56.-A la hora de dormir pienso que la gente se dará cuenta de mis problemas o de la torpeza de mis actos.|radio-56 | BM1: 57.- Escriba una situación en la que usted manifiesta frecuentemente alguna de estas respuestas o conductas.|text-1 | BN1: 57.1 - Me preocupo facilmente.|radio-57 | BO1: 57.2 - Tengo pensamientos o sentimientos negativos sobre mí, tales como "inferior" a los demás, "torpe", etc|radio-58 | BP1: 57.3 - Me siento inseguro de mí mismo.|radio-59 | BQ1: 57.4 - Doy demasiadas vueltas a las cosas sin llegar a decidirme.|radio-60 | BR1: 57.5 - Siento miedo.|radio-61 | BS1: 57.6 - Me cuesta concentrarme.|radio-62 | BT1: 57.7 - Pienso que la gente se dará cuenta de mis problemas o de la torpeza de mis actos.|radio-63 | BU1: 1.- Ante un examen en el que me juego mucho, o si voy a ser entrevistado para un trabajo importante me tiemblan las manos o las piernas.|radio-64 | BV1: 2.- Ante un examen en el que me juego mucho, o si voy a ser entrevistado para un trabajo importante me duele la cabeza.|radio-65 | BW1: 3.- Ante un examen en el que me juego mucho, o si voy a ser entrevistado para un trabajo importante mi cuerpo está en tensión.|radio-66 | BX1: 4.- Ante un examen en el que me juego mucho, o si voy a ser entrevistado para un trabajo importante me falta el aire y mi respiración es agitada.|radio-67 | BY1: 5.- Ante un examen en el que me juego mucho, o si voy a ser entrevistado para un trabajo importante siento náuseas o mareo.|radio-68 | BZ1: 6.- Ante un examen en el que me juego mucho, o si voy a ser entrevistado para un trabajo importante se me seca la boca y tengo dificultades para tragar.|radio-69 | CA1: 7.- Ante un examen en el que me juego mucho, o si voy a ser entrevistado para un trabajo importante tengo escalofríos y tirito aunque no haga mucho frío.|radio-70 | CB1: 8.- Cuando voy a llegar tarde a una cita siento molestias en el estómago.|radio-71 | CC1: 9.- Cuando voy a llegar tarde a una cita me sudan las manos u otra parte del cuerpo hasta en días fríos.|radio-72 | CD1: 10.- Cuando voy a llegar tarde a una cita me tiemblan las manos o las piernas.|radio-73 | CE1: 11.- Cuando voy a llegar tarde a una cita me duele la cabeza.|radio-74 | CF1: 12.- Cuando voy a llegar tarde a una cita tengo palpitaciones, el corazón me late muy deprisa.|radio-75 | CG1: 13.- Cuando voy a llegar tarde a una cita me falta el aire y mi respiración es agitada.|radio-76 | CH1: 14.- Cuando voy a llegar tarde a una cita se me seca la boca y tengo dificultades para tragar.|radio-77 | CI1: 15.- Cuando pienso en las muchas cosas que tengo que hacer siento molestias en el estómago.|radio-78 | CJ1: 16.- Cuando pienso en las muchas cosas que tengo que hacer me sudan las manos u otra parte del cuerpo hasta en días fríos.|radio-79 | CK1: 17.- Cuando pienso en las muchas cosas que tengo que hacer me tiemblan las manos o las piernas.|radio-80 | CL1: 18.- Cuando pienso en las muchas cosas que tengo que hacer me duele la cabeza.|radio-81 | CM1: 19.- Cuando pienso en las muchas cosas que tengo que hacer tengo palpitaciones, el corazón me late muy deprisa.|radio-82 | CN1: 20.- Cuando pienso en las muchas cosas que tengo que hacer me falta el aire y mi respiración es agitada.|radio-83 | CO1: 21.- Cuando pienso en las muchas cosas que tengo que hacer siento náuseas o mareo.|radio-84 | CP1: 22.- Cuando pienso en las muchas cosas que tengo que hacer se me seca la boca y tengo dificultades para tragar.|radio-85 | CQ1: 23.- A la hora de tomar una decisión o resolver un problema difícil me duele la cabeza.|radio-86 | CR1: 24.- En mi trabajo o cuando estudio siento molestias en el estómago.|radio-87 | CS1: 25.- En mi trabajo o cuando estudio me duele la cabeza.|radio-88 | CT1: 26.- En mi trabajo o cuando estudio tengo palpitaciones, el corazón me late muy deprisa.|radio-89 | CU1: 27.- En mi trabajo o cuando estudio se me seca la boca y tengo dificultades para tragar.|radio-90 | CV1: 28.- Cuando espero a alguien en un lugar un concurrido siento molestias en el estómago.|radio-91 | CW1: 29.- Cuando espero a alguien en un lugar un concurrido mi cuerpo está en tensión.|radio-92 | CX1: 30.- Cuando espero a alguien en un lugar un concurrido me falta el aire y mi respiración es agitada.|radio-93 | CY1: 31.- Cuando espero a alguien en un lugar un concurrido se me seca la boca y tengo dificultades para tragar.|radio-94 | CZ1: 32.- Si una persona del otro sexo está muy cerca de mí, rozándome , o si estoy en una situación sexual íntima me tiemblan las manos o las piernas.|radio-95 | DA1: 33.- Si una persona del otro sexo está muy cerca de mí, rozándome , o si estoy en una situación sexual íntima tengo palpitaciones, el corazón me late muy deprisa.|radio-96 | DB1: 34.- Si una persona del otro sexo está muy cerca de mí, rozándome , o si estoy en una situación sexual íntima me falta el aire y mi respiración es agitada.|radio-97 | DC1: 35.- Si una persona del otro sexo está muy cerca de mí, rozándome , o si estoy en una situación sexual íntima siento náuseas o mareo.|radio-98 | DD1: 36.- Si una persona del otro sexo está muy cerca de mí, rozándome , o si estoy en una situación sexual íntima se me seca la boca y tengo dificultades para tragar.|radio-99 | DE1: 37.- Cuando alguien me molesta o cuando discuto siento molestias en el estómago.|radio-100 | DF1: 38.- Cuando alguien me molesta o cuando discuto me tiemblan las manos o las piernas.|radio-101 | DG1: 39.- Cuando alguien me molesta o cuando discuto me duele la cabeza.|radio-102 | DH1: 40.- Cuando alguien me molesta o cuando discuto tengo palpitaciones, el corazón me late muy deprisa.|radio-103 | DI1: 41.- Cuando alguien me molesta o cuando discuto me falta el aire y mi respiración es agitada.|radio-104 | DJ1: 42.- Cuando alguien me molesta o cuando discuto siento náuseas o mareo.|radio-105 | DK1: 43.- Cuando alguien me molesta o cuando discuto se me seca la boca y tengo dificultades para tragar.|radio-106 | DL1: 44.- Cuando soy observado o mi trabajo es supervisado, cuando recibo críticas, o siempre que pueda ser evaluado negativamente me tiemblan las manos o las piernas.|radio-107 | DM1: 45.- Cuando soy observado o mi trabajo es supervisado, cuando recibo críticas, o siempre que pueda ser evaluado negativamente me falta el aire y mi respiración es agitada.|radio-108 | DN1: 46.- Cuando soy observado o mi trabajo es supervisado, cuando recibo críticas, o siempre que pueda ser evaluado negativamente siento náuseas o mareo.|radio-109 | DO1: 47.- Cuando soy observado o mi trabajo es supervisado, cuando recibo críticas, o siempre que pueda ser evaluado negativamente se me seca la boca y tengo dificultades para tragar.|radio-110 | DP1: 48.- Si tengo que hablar en público siento molestias en el estómago.|radio-111 | DQ1: 49.- Si tengo que hablar en público me tiemblan las manos o las piernas.|radio-112 | DR1: 50.- Si tengo que hablar en público me duele la cabeza.|radio-113 | DS1: 51.- Si tengo que hablar en público tengo palpitaciones, el corazón me late muy deprisa.|radio-114 | DT1: 52.- Si tengo que hablar en público me falta el aire y mi respiración es agitada.|radio-115 | DU1: 53.- Si tengo que hablar en público siento náuseas o mareo.|radio-116 | DV1: 54.- Si tengo que hablar en público se me seca la boca y tengo dificultades para tragar.|radio-117 | DW1: 55.- Si tengo que hablar en público tengo escalofríos y tirito aunque no haga mucho frío.|radio-118 | DX1: 56.- Cuando pienso en experiencias recientes en las que me he sentido ridículo, tímido, humillado, solo o rechazado mi cuerpo está en tensión.|radio-119 | DY1: 57.- Cuando pienso en experiencias recientes en las que me he sentido ridículo, tímido, humillado, solo o rechazado tengo palpitaciones, el corazón me late muy deprisa.|radio-120 | DZ1: 58.- Cuando pienso en experiencias recientes en las que me he sentido ridículo, tímido, humillado, solo o rechazado me falta el aire y mi respiración es agitada.|radio-121 | EA1: 59.- Cuando pienso en experiencias recientes en las que me he sentido ridículo, tímido, humillado, solo o rechazado tengo escalofríos y tirito aunque no haga mucho frío.|radio-122 | EB1: 60.- Cuando tengo que viajar en avión o en barco me sudan las manos u otra parte del cuerpo hasta en días fríos.|radio-123 | EC1: 61.- Cuando tengo que viajar en avión o en barco me tiemblan las manos o las piernas.|radio-124 | ED1: 62.- Cuando tengo que viajar en avión o en barco me duele la cabeza.|radio-125 | EE1: 63.- Cuando tengo que viajar en avión o en barco tengo palpitaciones, el corazón me late muy deprisa.|radio-126 | EF1: 64.- Cuando tengo que viajar en avión o en barco me falta el aire y mi respiración es agitada.|radio-127 | EG1: 65.- Cuando tengo que viajar en avión o en barco siento náuseas o mareo.|radio-128 | EH1: 66.- Cuando tengo que viajar en avión o en barco se me seca la boca y tengo dificultades para tragar.|radio-129 | EI1: 67.- Después de haber cometido algún error me sudan las manos u otra parte del cuerpo hasta en días fríos.|radio-130 | EJ1: 68.- Después de haber cometido algún error me tiemblan las manos o las piernas.|radio-131 | EK1: 69.- Después de haber cometido algún error me duele la cabeza.|radio-132 | EL1: 70.- Después de haber cometido algún error me falta el aire y mi respiración es agitada.|radio-133 | EM1: 71.- Después de haber cometido algún error tengo escalofríos y tirito aunque no haga mucho frío.|radio-134 | EN1: 72.- Ante la consulta del dentista, las inyecciones, las heridas o la sangre me duele la cabeza.|radio-135 | EO1: 73.- Ante la consulta del dentista, las inyecciones, las heridas o la sangre me falta el aire y mi respiración es agitada.|radio-136 | EP1: 74.- Ante la consulta del dentista, las inyecciones, las heridas o la sangre tengo escalofríos y tirito aunque no haga mucho frío.|radio-137 | EQ1: 75.- Cuando voy a una cita con una persona del otro sexo me tiemblan las manos o las piernas.|radio-138 | ER1: 76.- Cuando voy a una cita con una persona del otro sexo me duele la cabeza.|radio-139 | ES1: 77.- Cuando voy a una cita con una persona del otro sexo me falta el aire y mi respiración es agitada.|radio-140 | ET1: 78.- Cuando voy a una cita con una persona del otro sexo se me seca la boca y tengo dificultades para tragar.|radio-141 | EU1: 79.- Cuando pienso en mi futuro o en dificultades y problemas futuros me sudan las manos u otra parte del cuerpo hasta en días fríos.|radio-142 | EV1: 80.- Cuando pienso en mi futuro o en dificultades y problemas futuros me tiemblan las manos o las piernas.|radio-143 | EW1: 81.- Cuando pienso en mi futuro o en dificultades y problemas futuros me duele la cabeza.|radio-144 | EX1: 82.- Cuando pienso en mi futuro o en dificultades y problemas futuros mi cuerpo está en tensión.|radio-145 | EY1: 83.- Cuando pienso en mi futuro o en dificultades y problemas futuros me falta el aire y mi respiración es agitada.|radio-146 | EZ1: 84.- Cuando pienso en mi futuro o en dificultades y problemas futuros se me seca la boca y tengo dificultades para tragar.|radio-147 | FA1: 85.- En medio de multitudes o en espacios cerrados siento molestias en el estómago.|radio-148 | FB1: 86.- En medio de multitudes o en espacios cerrados me sudan las manos u otra parte del cuerpo hasta en días fríos.|radio-149 | FC1: 87.- En medio de multitudes o en espacios cerrados me tiemblan las manos o las piernas.|radio-150 | FD1: 88.- En medio de multitudes o en espacios cerrados me duele la cabeza.|radio-151 | FE1: 89.- En medio de multitudes o en espacios cerrados me falta el aire y mi respiración es agitada.|radio-152 | FF1: 90.- Cuando tengo que asistir a una reunión social o conocer gente nueva siento molestias en el estómago.|radio-153 | FG1: 91.- Cuando tengo que asistir a una reunión social o conocer gente nueva me tiemblan las manos o las piernas.|radio-154 | FH1: 92.- Cuando tengo que asistir a una reunión social o conocer gente nueva me duele la cabeza.|radio-155 | FI1: 93.- Cuando tengo que asistir a una reunión social o conocer gente nueva me falta el aire y mi respiración es agitada.|radio-156 | FJ1: 94.- Cuando tengo que asistir a una reunión social o conocer gente nueva se me seca la boca y tengo dificultades para tragar.|radio-157 | FK1: 95.- En lugares altos, o ante aguas profundas me tiemblan las manos o las piernas.|radio-158 | FL1: 96.- En lugares altos, o ante aguas profundas tengo palpitaciones, el corazón me late muy deprisa.|radio-159 | FM1: 97.- En lugares altos, o ante aguas profundas me falta el aire y mi respiración es agitada.|radio-160 | FN1: 98.- En lugares altos, o ante aguas profundas siento náuseas o mareo.|radio-161 | FO1: 99.- En lugares altos, o ante aguas profundas se me seca la boca y tengo dificultades para tragar.|radio-162 | FP1: 100.- En lugares altos, o ante aguas profundas tengo escalofríos y tirito aunque no haga mucho frío.|radio-163 | FQ1: 101.- Al observar escenas violentas siento molestias en el estómago.|radio-164 | FR1: 102.- Al observar escenas violentas tengo palpitaciones, el corazón me late muy deprisa.|radio-165 | FS1: 103.- Al observar escenas violentas me falta el aire y mi respiración es agitada.|radio-166 | FT1: 104.- Al observar escenas violentas siento náuseas o mareo.|radio-167 | FU1: 105.- Por nada en concreto siento molestias en el estómago.|radio-168 | FV1: 106.- Por nada en concreto me tiemblan las manos o las piernas.|radio-169 | FW1: 107.- Por nada en concreto me duele la cabeza.|radio-170 | FX1: 108.- Por nada en concreto tengo palpitaciones, el corazón me late muy deprisa.|radio-171 | FY1: 109.- Por nada en concreto me falta el aire y mi respiración es agitada.|radio-172 | FZ1: 110.- Por nada en concreto siento náuseas o mareo.|radio-173 | GA1: 111.- Por nada en concreto se me seca la boca y tengo dificultades para tragar.|radio-174 | GB1: 112.- A la hora de dormir me duele la cabeza.|radio-175 | GC1: 113.- Escriba una situación en la que usted manifiesta frecuentemente alguna de estas respuestas o conductas.|text-2 | GD1: 113.1 - Siento molestias en el estómago.|radio-176 | GE1: 113.2 - Me sudan las manos u otra parte del cuerpo hasta en días fríos.|radio-177 | GF1: 113.3 - Me tiemblan las manos o las piernas.|radio-178 | GG1: 113.4 - Me duele la cabeza.|radio-179 | GH1: 113.5 - Mi cuerpo está en tensión.|radio-180 | GI1: 113.6 - Tengo palpitaciones, el corazón me late muy deprisa.|radio-181 | GJ1: 113.7 - Me falta el aire y mi respiración es agitada.|radio-182 | GK1: 113.8 - Siento náuseas o mareo.|radio-183 | GL1: 113.9 - Se me seca la boca y tengo dificultades para tragar.|radio-184 | GM1: 113.10 - Tengo escalofrios y tirito aunque no haga mucho frio.|radio-241 | GN1: 1.- Ante un examen en el que me juego mucho, o si voy a ser entrevistado para un trabajo importante realizo movimientos repetitivos con alguna parte de mi cuerpo (rascarme, tocarme, movimientos rítmicos con pies o manos, etc.)|radio-185 | GO1: 2.- Ante un examen en el que me juego mucho, o si voy a ser entrevistado para un trabajo importante me muevo y hago cosas sin una finalidad concreta.|radio-186 | GP1: 3.- Ante un examen en el que me juego mucho, o si voy a ser entrevistado para un trabajo importante quedo paralizado o mis movimientos son torpes.|radio-187 | GQ1: 4.- Cuando voy a llegar tarde a una cita realizo movimientos repetitivos con alguna parte de mi cuerpo (rascarme, tocarme, movimientos rítmicos con pies o manos, etc.)|radio-188 | GR1: 5.- Cuando voy a llegar tarde a una cita me muevo y hago cosas sin una finalidad concreta.|radio-189 | GS1: 6.- Cuando pienso en las muchas cosas que tengo que hacer lloro con facilidad.|radio-190 | GT1: 7.- Cuando pienso en las muchas cosas que tengo que hacer realizo movimientos repetitivos con alguna parte de mi cuerpo (rascarme, tocarme, movimientos rítmicos con pies o manos, etc.)|radio-191 | GU1: 8.- Cuando pienso en las muchas cosas que tengo que hacer fumo, como o bebo demasiado.|radio-192 | GV1: 9.- Cuando pienso en las muchas cosas que tengo que hacer me muevo y hago cosas sin una finalidad concreta.|radio-193 | GW1: 10.- Cuando pienso en las muchas cosas que tengo que hacer quedo paralizado o mis movimientos son torpes.|radio-194 | GX1: 11.- Cuando pienso en las muchas cosas que tengo que hacer tartamudeo o tengo otras dificultades de expresión verbal.|radio-195 | GY1: 12.- A la hora de tomar una decisión o resolver un problema difícil fumo, como o bebo demasiado.|radio-196 | GZ1: 13.- A la hora de tomar una decisión o resolver un problema difícil me muevo y hago cosas sin una finalidad concreta.|radio-197 | HA1: 14.- A la hora de tomar una decisión o resolver un problema difícil tartamudeo o tengo otras dificultades de expresión verbal.|radio-198 | HB1: 15.- En mi trabajo o cuando estudio lloro con facilidad.|radio-199 | HC1: 16.- En mi trabajo o cuando estudio fumo, como o bebo demasiado.|radio-200 | HD1: 17.- En mi trabajo o cuando estudio quedo paralizado o mis movimientos son torpes.|radio-201 | HE1: 18.- Cuando espero a alguien en un lugar un concurrido fumo, como o bebo demasiado.|radio-202 | HF1: 19.- Cuando espero a alguien en un lugar un concurrido trato de evitar o rehuir la sítuación.|radio-203 | HG1: 20.- Si una persona del otro sexo está muy cerca de mí, rozándome , o si estoy en una situación sexual íntima fumo, como o bebo demasiado.|radio-204 | HH1: 21.- Cuando alguien me molesta o cuando discuto realizo movimientos repetitivos con alguna parte de mi cuerpo (rascarme, tocarme, movimientos rítmicos con pies o manos, etc.)|radio-205 | HI1: 22.- Cuando alguien me molesta o cuando discuto fumo, como o bebo demasiado.|radio-206 | HJ1: 23.- Cuando alguien me molesta o cuando discuto quedo paralizado o mis movimientos son torpes.|radio-207 | HK1: 24.- Cuando soy observado o mi trabajo es supervisado, cuando recibo críticas, o siempre que pueda ser evaluado negativamente realizo movimientos repetitivos con alguna parte de mi cuerpo (rascarme, tocarme, movimientos rítmicos con pies o manos, etc.)|radio-208 | HL1: 25.- Cuando soy observado o mi trabajo es supervisado, cuando recibo críticas, o siempre que pueda ser evaluado negativamente fumo, como o bebo demasiado.|radio-209 | HM1: 26.- Cuando soy observado o mi trabajo es supervisado, cuando recibo críticas, o siempre que pueda ser evaluado negativamente quedo paralizado o mis movimientos son torpes.|radio-210 | HN1: 27.- Si tengo que hablar en público fumo, como o bebo demasiado.|radio-211 | HO1: 28.- Cuando pienso en experiencias recientes en las que me he sentido ridículo, tímido, humillado, solo o rechazado realizo movimientos repetitivos con alguna parte de mi cuerpo (rascarme, tocarme, movimientos rítmicos con pies o manos, etc.)|radio-212 | HP1: 29.- Cuando pienso en experiencias recientes en las que me he sentido ridículo, tímido, humillado, solo o rechazado fumo, como o bebo demasiado.|radio-213 | HQ1: 30.- Cuando pienso en experiencias recientes en las que me he sentido ridículo, tímido, humillado, solo o rechazado me muevo y hago cosas sin una finalidad concreta.|radio-214 | HR1: 31.- Cuando tengo que viajar en avión o en barco realizo movimientos repetitivos con alguna parte de mi cuerpo (rascarme, tocarme, movimientos rítmicos con pies o manos, etc.)|radio-215 | HS1: 32.- Cuando tengo que viajar en avión o en barco trato de evitar o rehuir la sítuación.|radio-216 | HT1: 33.- Cuando tengo que viajar en avión o en barco me muevo y hago cosas sin una finalidad concreta.|radio-217 | HU1: 34.- Cuando tengo que viajar en avión o en barco quedo paralizado o mis movimientos son torpes.|radio-218 | HV1: 35.- Después de haber cometido algún error lloro con facilidad.|radio-219 | HW1: 36.- Después de haber cometido algún error fumo, como o bebo demasiado.|radio-220 | HX1: 37.- Ante la consulta del dentista, las inyecciones, las heridas o la sangre me muevo y hago cosas sin una finalidad concreta.|radio-221 | HY1: 38.- Ante la consulta del dentista, las inyecciones, las heridas o la sangre tartamudeo o tengo otras dificultades de expresión verbal.|radio-222 | HZ1: 39.- Cuando voy a una cita con una persona del otro sexo trato de evitar o rehuir la sítuación.|radio-223 | IA1: 40.- Cuando pienso en mi futuro o en dificultades y problemas futuros realizo movimientos repetitivos con alguna parte de mi cuerpo (rascarme, tocarme, movimientos rítmicos con pies o manos, etc.)|radio-224 | IB1: 41.- Cuando pienso en mi futuro o en dificultades y problemas futuros fumo, como o bebo demasiado.|radio-225 | IC1: 42.- En medio de multitudes o en espacios cerrados lloro con facilidad.|radio-226 | ID1: 43.- En medio de multitudes o en espacios cerrados realizo movimientos repetitivos con alguna parte de mi cuerpo (rascarme, tocarme, movimientos rítmicos con pies o manos, etc.)|radio-227 | IE1: 44.- En medio de multitudes o en espacios cerrados fumo, como o bebo demasiado.|radio-228 | IF1: 45.- En medio de multitudes o en espacios cerrados me muevo y hago cosas sin una finalidad concreta.|radio-229 | IG1: 46.- En medio de multitudes o en espacios cerrados quedo paralizado o mis movimientos son torpes.|radio-230 | IH1: 47.- Cuando tengo que asistir a una reunión social o conocer gente nueva lloro con facilidad.|radio-231 | II1: 48.- Cuando tengo que asistir a una reunión social o conocer gente nueva fumo, como o bebo demasiado.|radio-232 | IJ1: 49.- Cuando tengo que asistir a una reunión social o conocer gente nueva trato de evitar o rehuir la sítuación.|radio-233 | IK1: 50.- Cuando tengo que asistir a una reunión social o conocer gente nueva quedo paralizado o mis movimientos son torpes.|radio-234 | IL1: 51.- Cuando tengo que asistir a una reunión social o conocer gente nueva tartamudeo o tengo otras dificultades de expresión verbal.|radio-235 | IM1: 52.- En lugares altos, o ante aguas profundas quedo paralizado o mis movimientos son torpes.|radio-236 | IN1: 53.- Al observar escenas violentas fumo, como o bebo demasiado.|radio-237 | IO1: 54.- Al observar escenas violentas me muevo y hago cosas sin una finalidad concreta.|radio-238 | IP1: 55.- Por nada en concreto tartamudeo o tengo otras dificultades de expresión verbal.|radio-239 | IQ1: 56.- A la hora de dormir me muevo y hago cosas sin una finalidad concreta.|radio-240 | IR1: 57.- Escriba una situación en la que usted manifiesta frecuentemente alguna de estas respuestas o conductas.|text-3 | IS1: 57.1.- Lloro con facilidad.|radio-242 | IT1: 57.2.- Realizo movimientos repetitivos con alguna parte de mi cuerpo (rascarme, tocarme, movimientos rítmicos con pies o manos, etc.)|radio-243 | IU1: 57.3.- Fumo, como o bebo demasiado.|radio-244 | IV1: 57.4.- Trato de evitar o rehuir la sítuación.|radio-245 | IW1: 57.5.- Me muevo y hago cosas sin una finalidad concreta.|radio-246 | IX1: 57.6.- Quedo paralizado o mis movimientos son torpes.|radio-247 | IY1: 57.7.- Tartamudeo o tengo otras dificultades de expresión verbal.|radio-248 | IZ1: Las pruebas concluyeron ¿Acepta nuestros términos de uso?|consent-1 | JA1: ID|number-2
A2: 1 | B2: Luis Ángel Tovar Vázquez | C2: Hombre | D2: two | E2: 33 | F2: 07-10-1989 | G2: 20-08-2023 | H2: 12:17 am | I2: 0 | J2: 1 | K2: 2 | L2: 0 | M2: 1 | N2: 2 | O2: 1 | P2: 0 | Q2: 0 | R2: 0 | S2: 0 | T2: 0 | U2: 0 | V2: 0 | W2: 0 | X2: 0 | Y2: 0 | Z2: 0 | AA2: 0 | AB2: 0 | AC2: 0 | AD2: 0 | AE2: 2 | AF2: 0 | AG2: 0 | AH2: 0 | AI2: 1 | AJ2: 0 | AK2: 1 | AL2: 0 | AM2: 0 | AN2: 0 | AO2: 1 | AP2: 0 | AQ2: 0 | AR2: 0 | AS2: 0 | AT2: 0 | AU2: 0 | AV2: 0 | AW2: 1 | AX2: 0 | AY2: 0 | AZ2: 1 | BA2: 0 | BB2: 1 | BC2: 0 | BD2: 1 | BE2: 0 | BF2: 0 | BG2: 0 | BH2: 0 | BI2: 0 | BJ2: 0 | BK2: 0 | BL2: 0 | BM2: Cuando pienso el futuro de mis hijos me siento algunas veces con miedo e inseguro de su futuro | BN2: 1 | BO2: 0 | BP2: 1 | BQ2: 0 | BR2: 1 | BS2: 0 | BT2: 0 | BU2: 0 | BV2: 0 | BW2: 0 | BX2: 0 | BY2: 0 | BZ2: 0 | CA2: 0 | CB2: 0 | CC2: 0 | CD2: 0 | CE2: 0 | CF2: 0 | CG2: 0 | CH2: 0 | CI2: 1 | CJ2: 0 | CK2: 0 | CL2: 2 | CM2: 0 | CN2: 0 | CO2: 0 | CP2: 0 | CQ2: 1 | CR2: 0 | CS2: 0 | CT2: 0 | CU2: 0 | CV2: 0 | CW2: 0 | CX2: 0 | CY2: 0 | CZ2: 0 | DA2: 0 | DB2: 0 | DC2: 0 | DD2: 0 | DE2: 0 | DF2: 0 | DG2: 1 | DH2: 0 | DI2: 1 | DJ2: 0 | DK2: 0 | DL2: 0 | DM2: 0 | DN2: 0 | DO2: 0 | DP2: 1 | DQ2: 0 | DR2: 0 | DS2: 0 | DT2: 0 | DU2: 0 | DV2: 0 | DW2: 0 | DX2: 1 | DY2: 0 | DZ2: 0 | EA2: 0 | EB2: 0 | EC2: 0 | ED2: 0 | EE2: 0 | EF2: 0 | EG2: 0 | EH2: 0 | EI2: 0 | EJ2: 0 | EK2: 1 | EL2: 0 | EM2: 0 | EN2: 0 | EO2: 0 | EP2: 0 | EQ2: 0 | ER2: 0 | ES2: 0 | ET2: 0 | EU2: 0 | EV2: 0 | EW2: 1 | EX2: 1 | EY2: 0 | EZ2: 0 | FA2: 0 | FB2: 0 | FC2: 0 | FD2: 1 | FE2: 2 | FF2: 0 | FG2: 0 | FH2: 0 | FI2: 0 | FJ2: 0 | FK2: 1 | FL2: 1 | FM2: 0 | FN2: 0 | FO2: 0 | FP2: 0 | FQ2: 0 | FR2: 0 | FS2: 0 | FT2: 0 | FU2: 1 | FV2: 0 | FW2: 2 | FX2: 0 | FY2: 0 | FZ2: 0 | GA2: 0 | GB2: 0 | GC2: Preocupación y estrés por el futuro de mis hijo | GD2: 0 | GE2: 0 | GF2: 0 | GG2: 1 | GH2: 2 | GI2: 0 | GJ2: 0 | GK2: 0 | GL2: 0 | GM2: 0 | GN2: 2 | GO2: 1 | GP2: 0 | GQ2: 0 | GR2: 0 | GS2: 0 | GT2: 0 | GU2: 1 | GV2: 0 | GW2: 0 | GX2: 0 | GY2: 0 | GZ2: 0 | HA2: 0 | HB2: 0 | HC2: 1 | HD2: 0 | HE2: 0 | HF2: 0 | HG2: 0 | HH2: 0 | HI2: 1 | HJ2: 0 | HK2: 0 | HL2: 0 | HM2: 0 | HN2: 0 | HO2: 0 | HP2: 0 | HQ2: 0 | HR2: 0 | HS2: 0 | HT2: 0 | HU2: 0 | HV2: 1 | HW2: 1 | HX2: 0 | HY2: 0 | HZ2: 0 | IA2: 0 | IB2: 1 | IC2: 0 | ID2: 0 | IE2: 0 | IF2: 0 | IG2: 0 | IH2: 0 | II2: 1 | IJ2: 0 | IK2: 0 | IL2: 0 | IM2: 1 | IN2: 0 | IO2: 0 | IP2: 1 | IQ2: 0 | IS2: 0 | IT2: 0 | IU2: 0 | IV2: 0 | IW2: 0 | IX2: 0 | IY2: 0 | IZ2: marcada
A3: 2 | B3: Luis Emiliano Medina Hernández | C3: Hombre | D3: one | E3: 17 | F3: 19-07-2006 | G3: 23-08-2023 | H3: 05:13 pm | I3: 2 | J3: 2 | K3: 2 | L3: 3 | M3: 3 | N3: 1 | O3: 1 | P3: 0 | Q3: 1 | R3: 0 | S3: 0 | T3: 0 | U3: 0 | V3: 0 | W3: 0 | X3: 0 | Y3: 0 | Z3: 0 | AA3: 0 | AB3: 0 | AC3: 0 | AD3: 0 | AE3: 0 | AF3: 0 | AG3: 0 | AH3: 0 | AI3: 1 | AJ3: 0 | AK3: 1 | AL3: 1 | AM3: 0 | AN3: 0 | AO3: 0 | AP3: 0 | AQ3: 0 | AR3: 0 | AS3: 0 | AT3: 0 | AU3: 0 | AV3: 0 | AW3: 0 | AX3: 0 | AY3: 0 | AZ3: 0 | BA3: 0 | BB3: 0 | BC3: 0 | BD3: 0 | BE3: 0 | BF3: 0 | BG3: 0 | BH3: 0 | BI3: 0 | BJ3: 1 | BK3: 0 | BL3: 0 | BN3: 0 | BO3: 0 | BP3: 0 | BQ3: 0 | BR3: 0 | BS3: 0 | BT3: 0 | BU3: 0 | BV3: 0 | BW3: 0 | BX3: 0 | BY3: 0 | BZ3: 0 | CA3: 0 | CB3: 0 | CC3: 0 | CD3: 0 | CE3: 0 | CF3: 0 | CG3: 0 | CH3: 0 | CI3: 0 | CJ3: 0 | CK3: 0 | CL3: 0 | CM3: 0 | CN3: 0 | CO3: 0 | CP3: 0 | CQ3: 0 | CR3: 0 | CS3: 0 | CT3: 0 | CU3: 0 | CV3: 0 | CW3: 0 | CX3: 0 | CY3: 0 | CZ3: 0 | DA3: 0 | DB3: 0 | DC3: 0 | DD3: 0 | DE3: 0 | DF3: 0 | DG3: 0 | DH3: 0 | DI3: 0 | DJ3: 0 | DK3: 0 | DL3: 0 | DM3: 0 | DN3: 0 | DO3: 0 | DP3: 0 | DQ3: 0 | DR3: 0 | DS3: 0 | DT3: 0 | DU3: 0 | DV3: 0 | DW3: 0 | DX3: 0 | DY3: 0 | DZ3: 0 | EA3: 0 | EB3: 0 | EC3: 0 | ED3: 0 | EE3: 0 | EF3: 0 | EG3: 0 | EH3: 0 | EI3: 0 | EJ3: 0 | EK3: 0 | EL3: 0 | EM3: 0 | EN3: 0 | EO3: 0 | EP3: 0 | EQ3: 0 | ER3: 0 | ES3: 0 | ET3: 0 | EU3: 0 | EV3: 0 | EW3: 0 | EX3: 0 | EY3: 0 | EZ3: 0 | FA3: 0 | FB3: 0 | FC3: 0 | FD3: 0 | FE3: 0 | FF3: 0 | FG3: 0 | FH3: 0 | FI3: 0 | FJ3: 0 | FK3: 0 | FL3: 0 | FM3: 0 | FN3: 0 | FO3: 0 | FP3: 0 | FQ3: 0 | FR3: 0 | FS3: 0 | FT3: 0 | FU3: 0 | FV3: 0 | FW3: 0 | FX3: 0 | FY3: 0 | FZ3: 0 | GA3: 0 | GB3: 0 | GD3: 0 | GE3: 0 | GF3: 0 | GG3: 0 | GH3: 0 | GI3: 0 | GJ3: 0 | GK3: 0 | GL3: 0 | GM3: 0 | GN3: 1 | GO3: 1 | GP3: 0 | GQ3: 1 | GR3: 1 | GS3: 0 | GT3: 3 | GU3: 0 | GV3: 2 | GW3: 0 | GX3: 0 | GY3: 0 | GZ3: 1 | HA3: 0 | HB3: 0 | HC3: 0 | HD3: 0 | HE3: 0 | HF3: 0 | HG3: 0 | HH3: 0 | HI3: 0 | HJ3: 0 | HK3: 0 | HL3: 0 | HM3: 0 | HN3: 0 | HO3: 1 | HP3: 0 | HQ3: 1 | HR3: 0 | HS3: 0 | HT3: 0 | HU3: 0 | HV3: 0 | HW3: 0 | HX3: 0 | HY3: 0 | HZ3: 0 | IA3: 2 | IB3: 0 | IC3: 0 | ID3: 0 | IE3: 0 | IF3: 0 | IG3: 0 | IH3: 0 | II3: 0 | IJ3: 0 | IK3: 0 | IL3: 0 | IM3: 0 | IN3: 0 | IO3: 0 | IP3: 0 | IQ3: 2 | IS3: 0 | IT3: 0 | IU3: 0 | IV3: 0 | IW3: 0 | IX3: 0 | IY3: 0 | IZ3: marcada
A4: 4 | B4: Nicole Esmeralda De La Rosa Vazquez | C4: Mujer | D4: one | E4: 21 | F4: 08-08-2002 | G4: 20-09-2023 | H4: 01:24 pm | I4: 3 | J4: 3 | K4: 2 | L4: 3 | M4: 3 | N4: 2 | O4: 2 | P4: 1 | Q4: 2 | R4: 1 | S4: 0 | T4: 0 | U4: 0 | V4: 1 | W4: 2 | X4: 0 | Y4: 2 | Z4: 2 | AA4: 2 | AB4: 2 | AC4: 2 | AD4: 2 | AE4: 3 | AF4: 0 | AG4: 1 | AH4: 1 | AI4: 2 | AJ4: 3 | AK4: 2 | AL4: 2 | AM4: 3 | AN4: 1 | AO4: 3 | AP4: 2 | AQ4: 1 | AR4: 3 | AS4: 2 | AT4: 1 | AU4: 1 | AV4: 1 | AW4: 2 | AX4: 2 | AY4: 2 | AZ4: 3 | BA4: 1 | BB4: 2 | BC4: 1 | BD4: 2 | BE4: 2 | BF4: 2 | BG4: 1 | BH4: 2 | BI4: 2 | BJ4: 2 | BK4: 2 | BL4: 1 | BU4: 3 | BV4: 2 | BW4: 3 | BX4: 3 | BY4: 2 | BZ4: 1 | CA4: 3 | CB4: 2 | CC4: 2 | CD4: 2 | CE4: 1 | CF4: 2 | CG4: 2 | CH4: 2 | CI4: 2 | CJ4: 3 | CK4: 3 | CL4: 4 | CM4: 3 | CN4: 3 | CO4: 2 | CP4: 2 | CQ4: 3 | CR4: 2 | CS4: 2 | CT4: 2 | CU4: 1 | CV4: 2 | CW4: 2 | CX4: 2 | CY4: 1 | CZ4: 1 | DA4: 2 | DB4: 1 | DC4: 1 | DD4: 1 | DE4: 2 | DF4: 2 | DG4: 3 | DH4: 3 | DI4: 2 | DJ4: 2 | DK4: 2 | DL4: 2 | DM4: 3 | DN4: 2 | DO4: 1 | DP4: 2 | DQ4: 3 | DR4: 2 | DS4: 4 | DT4: 4 | DU4: 3 | DV4: 1 | DW4: 3 | DX4: 2 | DY4: 2 | DZ4: 2 | EA4: 2 | EB4: 3 | EC4: 2 | ED4: 2 | EE4: 3 | EF4: 2 | EG4: 2 | EH4: 1 | EI4: 3 | EJ4: 3 | EK4: 3 | EL4: 3 | EM4: 3 | EN4: 3 | EO4: 3 | EP4: 3 | EQ4: 2 | ER4: 1 | ES4: 1 | ET4: 1 | EU4: 3 | EV4: 3 | EW4: 3 | EX4: 3 | EY4: 3 | EZ4: 2 | FA4: 2 | FB4: 2 | FC4: 2 | FD4: 2 | FE4: 2 | FF4: 1 | FG4: 1 | FH4: 2 | FI4: 1 | FJ4: 1 | FK4: 2 | FL4: 3 | FM4: 3 | FN4: 2 | FO4: 1 | FP4: 2 | FQ4: 2 | FR4: 2 | FS4: 2 | FT4: 2 | FU4: 2 | FV4: 2 | FW4: 3 | FX4: 3 | FY4: 3 | FZ4: 3 | GA4: 1 | GB4: 2 | GC4: Tener ganas de vomitar | GD4: 4 | GE4: 4 | GF4: 4 | GG4: 4 | GH4: 3 | GI4: 3 | GJ4: 3 | GK4: 4 | GL4: 3 | GM4: 4 | GN4: 4 | GO4: 4 | GP4: 3 | GQ4: 3 | GR4: 3 | GS4: 3 | GT4: 3 | GU4: 0 | GV4: 3 | GW4: 2 | GX4: 1 | GY4: 0 | GZ4: 4 | HA4: 1 | HB4: 2 | HC4: 0 | HD4: 2 | HE4: 0 | HF4: 2 | HG4: 0 | HH4: 4 | HI4: 0 | HJ4: 2 | HK4: 4 | HL4: 0 | HM4: 3 | HN4: 0 | HO4: 3 | HP4: 0 | HQ4: 3 | HR4: 3 | HS4: 2 | HT4: 2 | HU4: 2 | HV4: 3 | HW4: 0 | HX4: 3 | HY4: 1 | HZ4: 2 | IA4: 3 | IB4: 0 | IC4: 1 | ID4: 2 | IE4: 0 | IF4: 2 | IG4: 1 | IH4: 0 | II4: 0 | IJ4: 1 | IK4: 1 | IL4: 2 | IM4: 2 | IN4: 0 | IO4: 1 | IP4: 0 | IQ4: 3 | IR4: Cuando veo a mi ex pareja o cuando siento ganas de vomitar | IS4: 3 | IT4: 3 | IU4: 0 | IV4: 3 | IW4: 3 | IX4: 3 | IY4: 3 | IZ4: marcada
A5: 5 | B5: Aldo Froylan Flores Flores | C5: Hombre | D5: one | E5: 18 | F5: 19-10-2005 | G5: 11-10-2023 | H5: 03:10 pm | I5: 0 | J5: 1 | K5: 2 | L5: 0 | M5: 1 | N5: 0 | O5: 0 | P5: 0 | Q5: 0 | R5: 0 | S5: 0 | T5: 0 | U5: 0 | V5: 0 | W5: 1 | X5: 0 | Y5: 2 | Z5: 1 | AA5: 2 | AB5: 1 | AC5: 1 | AD5: 0 | AE5: 3 | AF5: 0 | AG5: 0 | AH5: 0 | AI5: 0 | AJ5: 1 | AK5: 1 | AL5: 1 | AM5: 0 | AN5: 1 | AO5: 0 | AP5: 0 | AQ5: 0 | AR5: 0 | AS5: 0 | AT5: 0 | AU5: 1 | AV5: 1 | AW5: 1 | AX5: 0 | AY5: 1 | AZ5: 1 | BA5: 0 | BB5: 0 | BC5: 0 | BD5: 2 | BE5: 1 | BF5: 0 | BG5: 1 | BH5: 0 | BI5: 0 | BJ5: 0 | BK5: 0 | BL5: 0 | BM5: Miedo al rachazo | BN5: 0 | BO5: 0 | BP5: 0 | BQ5: 0 | BR5: 0 | BS5: 1 | BT5: 0 | BU5: 0 | BV5: 0 | BW5: 0 | BX5: 0 | BY5: 0 | BZ5: 0 | CA5: 0 | CB5: 0 | CC5: 3 | CD5: 0 | CE5: 0 | CF5: 0 | CG5: 0 | CH5: 0 | CI5: 0 | CJ5: 3 | CK5: 0 | CL5: 0 | CM5: 0 | CN5: 0 | CO5: 0 | CP5: 0 | CQ5: 0 | CR5: 0 | CS5: 0 | CT5: 0 | CU5: 0 | CV5: 0 | CW5: 0 | CX5: 0 | CY5: 0 | CZ5: 1 | DA5: 3 | DB5: 2 | DC5: 0 | DD5: 0 | DE5: 0 | DF5: 0 | DG5: 0 | DH5: 1 | DI5: 0 | DJ5: 0 | DK5: 0 | DL5: 0 | DM5: 0 | DN5: 0 | DO5: 0 | DP5: 2 | DQ5: 1 | DR5: 0 | DS5: 3 | DT5: 1 | DU5: 0 | DV5: 0 | DW5: 2 | DX5: 1 | DY5: 2 | DZ5: 0 | EA5: 0 | EB5: 0 | EC5: 0 | ED5: 0 | EE5: 0 | EF5: 0 | EG5: 0 | EH5: 0 | EI5: 3 | EJ5: 0 | EK5: 0 | EL5: 0 | EM5: 0 | EN5: 0 | EO5: 0 | EP5: 0 | EQ5: 0 | ER5: 0 | ES5: 0 | ET5: 0 | EU5: 0 | EV5: 0 | EW5: 0 | EX5: 0 | EY5: 0 | EZ5: 0 | FA5: 0 | FB5: 2 | FC5: 0 | FD5: 0 | FE5: 0 | FF5: 0 | FG5: 0 | FH5: 0 | FI5: 0 | FJ5: 0 | FK5: 0 | FL5: 2 | FM5: 0 | FN5: 0 | FO5: 0 | FP5: 0 | FQ5: 0 | FR5: 0 | FS5: 0 | FT5: 0 | FU5: 1 | FV5: 0 | FW5: 1 | FX5: 1 | FY5: 0 | FZ5: 0 | GA5: 0 | GB5: 0 | GC5: Sudoracion en manos | GD5: 0 | GE5: 2 | GF5: 0 | GG5: 0 | GH5: 0 | GI5: 0 | GJ5: 0 | GK5: 0 | GL5: 0 | GM5: 0 | GN5: 0 | GO5: 0 | GP5: 0 | GQ5: 1 | GR5: 0 | GS5: 0 | GT5: 0 | GU5: 1 | GV5: 0 | GW5: 0 | GX5: 0 | GY5: 0 | GZ5: 0 | HA5: 1 | HB5: 2 | HC5: 0 | HD5: 0 | HE5: 0 | HF5: 1 | HG5: 0 | HH5: 0 | HI5: 0 | HJ5: 0 | HK5: 0 | HL5: 0 | HM5: 0 | HN5: 0 | HO5: 1 | HP5: 1 | HQ5: 0 | HR5: 0 | HS5: 0 | HT5: 0 | HU5: 0 | HV5: 0 | HW5: 1 | HX5: 0 | HY5: 0 | HZ5: 0 | IA5: 0 | IB5: 2 | IC5: 0 | ID5: 0 | IE5: 0 | IF5: 0 | IG5: 0 | IH5: 0 | II5: 0 | IJ5: 0 | IK5: 0 | IL5: 0 | IM5: 0 | IN5: 0 | IO5: 0 | IP5: 0 | IQ5: 0 | IR5: Solía fumar despues de cometer un error | IS5: 0 | IT5: 0 | IU5: 0 | IV5: 0 | IW5: 0 | IX5: 0 | IY5: 0 | IZ5: marcada
A6: 6 | B6: DANTE HUMBERTO CANTU PACHICANO | C6: Hombre | D6: one | E6: 29 | F6: 17-07-1994 | G6: 12-10-2023 | H6: 09:46 pm | I6: 0 | J6: 0 | K6: 0 | L6: 0 | M6: 0 | N6: 0 | O6: 0 | P6: 0 | Q6: 0 | R6: 0 | S6: 0 | T6: 0 | U6: 0 | V6: 0 | W6: 0 | X6: 0 | Y6: 0 | Z6: 0 | AA6: 0 | AB6: 0 | AC6: 0 | AD6: 0 | AE6: 0 | AF6: 0 | AG6: 0 | AH6: 0 | AI6: 0 | AJ6: 1 | AK6: 0 | AL6: 0 | AM6: 0 | AN6: 0 | AO6: 0 | AP6: 0 | AQ6: 0 | AR6: 0 | AS6: 0 | AT6: 0 | AU6: 0 | AV6: 0 | AW6: 0 | AX6: 0 | AY6: 0 | AZ6: 0 | BA6: 0 | BB6: 2 | BC6: 0 | BD6: 1 | BE6: 0 | BF6: 0 | BG6: 0 | BH6: 0 | BI6: 0 | BJ6: 0 | BK6: 0 | BL6: 0 | BM6: VIAJAR SOLO AL OTRO PAIS QUE NUNCA HE ESTADO | BN6: 2 | BO6: 0 | BP6: 0 | BQ6: 0 | BR6: 2 | BS6: 0 | BT6: 0 | BU6: 0 | BV6: 0 | BW6: 0 | BX6: 0 | BY6: 0 | BZ6: 0 | CA6: 0 | CB6: 0 | CC6: 0 | CD6: 0 | CE6: 0 | CF6: 0 | CG6: 0 | CH6: 0 | CI6: 0 | CJ6: 0 | CK6: 0 | CL6: 0 | CM6: 0 | CN6: 0 | CO6: 0 | CP6: 0 | CQ6: 0 | CR6: 0 | CS6: 0 | CT6: 0 | CU6: 0 | CV6: 0 | CW6: 0 | CX6: 0 | CY6: 0 | CZ6: 0 | DA6: 0 | DB6: 0 | DC6: 0 | DD6: 0 | DE6: 0 | DF6: 0 | DG6: 0 | DH6: 0 | DI6: 0 | DJ6: 0 | DK6: 0 | DL6: 0 | DM6: 0 | DN6: 0 | DO6: 0 | DP6: 0 | DQ6: 0 | DR6: 0 | DS6: 0 | DT6: 0 | DU6: 0 | DV6: 0 | DW6: 0 | DX6: 0 | DY6: 0 | DZ6: 0 | EA6: 0 | EB6: 0 | EC6: 0 | ED6: 0 | EE6: 0 | EF6: 0 | EG6: 0 | EH6: 0 | EI6: 0 | EJ6: 0 | EK6: 0 | EL6: 0 | EM6: 0 | EN6: 0 | EO6: 0 | EP6: 0 | EQ6: 0 | ER6: 0 | ES6: 0 | ET6: 0 | EU6: 0 | EV6: 0 | EW6: 0 | EX6: 0 | EY6: 0 | EZ6: 0 | FA6: 0 | FB6: 0 | FC6: 0 | FD6: 0 | FE6: 0 | FF6: 0 | FG6: 0 | FH6: 0 | FI6: 0 | FJ6: 0 | FK6: 0 | FL6: 0 | FM6: 0 | FN6: 0 | FO6: 0 | FP6: 0 | FQ6: 0 | FR6: 0 | FS6: 0 | FT6: 0 | FU6: 0 | FV6: 0 | FW6: 0 | FX6: 0 | FY6: 0 | FZ6: 0 | GA6: 0 | GB6: 0 | GC6: VIAJAR SOLO AL OTRO PAIS EN DONDE NUNCA HE ESTADO | GD6: 0 | GE6: 0 | GF6: 0 | GG6: 0 | GH6: 0 | GI6: 0 | GJ6: 0 | GK6: 0 | GL6: 0 | GM6: 0 | GN6: 0 | GO6: 0 | GP6: 0 | GQ6: 0 | GR6: 0 | GS6: 0 | GT6: 0 | GU6: 0 | GV6: 0 | GW6: 0 | GX6: 0 | GY6: 0 | GZ6: 0 | HA6: 0 | HB6: 0 | HC6: 0 | HD6: 0 | HE6: 2 | HF6: 0 | HG6: 0 | HH6: 0 | HI6: 0 | HJ6: 0 | HK6: 0 | HL6: 0 | HM6: 0 | HN6: 0 | HO6: 0 | HP6: 0 | HQ6: 0 | HR6: 0 | HS6: 2 | HT6: 0 | HU6: 0 | HV6: 0 | HW6: 0 | HX6: 0 | HY6: 0 | HZ6: 0 | IA6: 0 | IB6: 0 | IC6: 0 | ID6: 0 | IE6: 0 | IF6: 0 | IG6: 0 | IH6: 0 | II6: 0 | IJ6: 0 | IK6: 0 | IL6: 0 | IM6: 0 | IN6: 0 | IO6: 0 | IP6: 0 | IQ6: 0 | IR6: VIAJAR SOLO AL OTRO PAIS DONDE NUNCA HE ESTADO | IS6: 0 | IT6: 0 | IU6: 0 | IV6: 0 | IW6: 0 | IX6: 0 | IY6: 0 | IZ6: marcada
A7: 7 | B7: DIANA LAURA GOMEZ MADRIGAL | C7: Mujer | D7: one | E7: 26 | F7: 04-08-1997 | G7: 14-10-2023 | H7: 04:37 pm | I7: 2 | J7: 1 | K7: 4 | L7: 3 | M7: 3 | N7: 2 | O7: 3 | P7: 2 | Q7: 3 | R7: 1 | S7: 2 | T7: 1 | U7: 2 | V7: 1 | W7: 2 | X7: 1 | Y7: 3 | Z7: 3 | AA7: 2 | AB7: 1 | AC7: 1 | AD7: 1 | AE7: 2 | AF7: 2 | AG7: 1 | AH7: 1 | AI7: 3 | AJ7: 2 | AK7: 3 | AL7: 3 | AM7: 2 | AN7: 2 | AO7: 3 | AP7: 2 | AQ7: 2 | AR7: 2 | AS7: 2 | AT7: 2 | AU7: 2 | AV7: 1 | AW7: 2 | AX7: 1 | AY7: 2 | AZ7: 3 | BA7: 1 | BB7: 3 | BC7: 1 | BD7: 3 | BE7: 1 | BF7: 2 | BG7: 2 | BH7: 4 | BI7: 2 | BJ7: 2 | BK7: 2 | BL7: 2 | BM7: En el trabajo o cuando conozco a un gpo de gente nueva | BP7: 2 | BQ7: 4 | BR7: 3 | BS7: 4 | BT7: 4 | BU7: 2 | BV7: 1 | BW7: 1 | BX7: 1 | BY7: 1 | BZ7: 3 | CA7: 2 | CB7: 2 | CC7: 1 | CD7: 1 | CE7: 0 | CF7: 1 | CG7: 0 | CH7: 0 | CI7: 2 | CJ7: 1 | CK7: 0 | CL7: 0 | CM7: 1 | CN7: 0 | CO7: 0 | CP7: 0 | CQ7: 0 | CR7: 1 | CS7: 2 | CT7: 2 | CU7: 3 | CV7: 1 | CW7: 1 | CX7: 1 | CY7: 0 | CZ7: 0 | DA7: 2 | DB7: 0 | DC7: 0 | DD7: 2 | DE7: 2 | DF7: 1 | DG7: 0 | DH7: 4 | DI7: 4 | DJ7: 2 | DK7: 3 | DL7: 3 | DM7: 2 | DN7: 1 | DO7: 3 | DP7: 1 | DQ7: 2 | DR7: 0 | DS7: 3 | DT7: 1 | DU7: 1 | DV7: 3 | DW7: 1 | DX7: 1 | DY7: 1 | DZ7: 1 | EA7: 1 | EB7: 2 | EC7: 2 | ED7: 1 | EE7: 1 | EF7: 1 | EG7: 0 | EH7: 1 | EI7: 4 | EJ7: 3 | EK7: 0 | EL7: 3 | EM7: 0 | EN7: 0 | EO7: 1 | EP7: 0 | EQ7: 2 | ER7: 0 | ES7: 1 | ET7: 2 | EU7: 3 | EV7: 2 | EW7: 1 | EX7: 3 | EY7: 0 | EZ7: 0 | FA7: 1 | FB7: 1 | FC7: 1 | FD7: 2 | FE7: 0 | FF7: 2 | FG7: 2 | FH7: 0 | FI7: 1 | FJ7: 2 | FK7: 2 | FL7: 3 | FM7: 1 | FN7: 1 | FO7: 1 | FP7: 2 | FQ7: 3 | FR7: 2 | FS7: 2 | FT7: 1 | FU7: 0 | FV7: 2 | FW7: 2 | FX7: 2 | FY7: 2 | FZ7: 2 | GA7: 1 | GB7: 1 | GC7: en el trabajo o con un gpo de gente que no conozco | GD7: 0 | GE7: 2 | GF7: 2 | GG7: 1 | GH7: 3 | GI7: 2 | GJ7: 2 | GK7: 2 | GL7: 1 | GM7: 1 | GN7: 2 | GO7: 3 | GP7: 2 | GQ7: 0 | GR7: 0 | GS7: 1 | GT7: 2 | GU7: 2 | GV7: 1 | GW7: 2 | GX7: 1 | GY7: 2 | GZ7: 2 | HA7: 2 | HB7: 2 | HC7: 2 | HD7: 3 | HE7: 1 | HF7: 2 | HG7: 0 | HH7: 4 | HI7: 1 | HJ7: 2 | HK7: 3 | HL7: 0 | HM7: 3 | HN7: 0 | HO7: 2 | HP7: 0 | HQ7: 1 | HR7: 1 | HS7: 0 | HT7: 1 | HU7: 2 | HV7: 2 | HW7: 2 | HX7: 2 | HY7: 2 | HZ7: 1 | IA7: 2 | IB7: 2 | IC7: 0 | ID7: 2 | IE7: 1 | IF7: 3 | IG7: 3 | IH7: 0 | II7: 1 | IJ7: 1 | IK7: 3 | IL7: 2 | IM7: 1 | IN7: 1 | IO7: 1 | IP7: 2 | IQ7: 1 | IR7: en el trabajo, reuniones o al conocer un gpo de gente nueva | IS7: 2 | IT7: 2 | IU7: 2 | IV7: 2 | IW7: 2 | IX7: 3 | IY7: 2 | IZ7: marcada
A8: 8 | B8: Jesus Humberto perales soto | C8: Hombre | D8: one | E8: 15 | F8: 11-07-2008 | G8: 24-10-2023 | H8: 05:16 pm | I8: 1 | J8: 1 | K8: 1 | L8: 1 | M8: 1 | N8: 0 | O8: 0 | P8: 0 | Q8: 0 | R8: 0 | S8: 2 | T8: 1 | U8: 0 | V8: 0 | W8: 0 | X8: 0 | Y8: 0 | Z8: 0 | AA8: 0 | AB8: 0 | AC8: 0 | AD8: 0 | AE8: 0 | AF8: 0 | AG8: 0 | AH8: 0 | AI8: 0 | AJ8: 0 | AK8: 0 | AL8: 0 | AM8: 0 | AN8: 0 | AO8: 1 | AP8: 0 | AQ8: 0 | AR8: 0 | AS8: 3 | AT8: 0 | AU8: 0 | AV8: 0 | AW8: 0 | AX8: 0 | AY8: 1 | AZ8: 4 | BA8: 0 | BB8: 0 | BC8: 0 | BD8: 1 | BE8: 0 | BF8: 0 | BG8: 0 | BH8: 0 | BI8: 0 | BJ8: 0 | BK8: 0 | BL8: 0 | BN8: 4 | BO8: 0 | BP8: 1 | BQ8: 1 | BR8: 1 | BS8: 1 | BT8: 0 | BU8: 0 | BV8: 0 | BW8: 0 | BX8: 0 | BY8: 0 | BZ8: 0 | CA8: 0 | CB8: 1 | CC8: 1 | CD8: 0 | CE8: 0 | CF8: 1 | CG8: 0 | CH8: 0 | CI8: 0 | CJ8: 0 | CK8: 0 | CL8: 0 | CM8: 0 | CN8: 0 | CO8: 0 | CP8: 0 | CQ8: 0 | CR8: 0 | CS8: 0 | CT8: 0 | CU8: 0 | CV8: 0 | CW8: 1 | CX8: 0 | CY8: 0 | CZ8: 0 | DA8: 0 | DB8: 0 | DC8: 0 | DD8: 0 | DE8: 0 | DF8: 0 | DG8: 0 | DH8: 0 | DI8: 0 | DJ8: 0 | DK8: 0 | DL8: 0 | DM8: 0 | DN8: 0 | DO8: 0 | DP8: 0 | DQ8: 0 | DR8: 0 | DS8: 0 | DT8: 0 | DU8: 0 | DV8: 0 | DW8: 0 | DX8: 0 | DY8: 0 | DZ8: 0 | EA8: 0 | EB8: 0 | EC8: 0 | ED8: 0 | EE8: 0 | EF8: 0 | EG8: 0 | EH8: 0 | EI8: 0 | EJ8: 1 | EK8: 0 | EL8: 0 | EM8: 0 | EN8: 0 | EO8: 0 | EP8: 0 | EQ8: 1 | ER8: 0 | ES8: 0 | ET8: 0 | EU8: 0 | EV8: 0 | EW8: 0 | EX8: 0 | EY8: 0 | EZ8: 0 | FA8: 0 | FB8: 0 | FC8: 0 | FD8: 0 | FE8: 0 | FF8: 0 | FG8: 0 | FH8: 0 | FI8: 0 | FJ8: 0 | FK8: 0 | FL8: 0 | FM8: 0 | FN8: 0 | FO8: 0 | FP8: 1 | FQ8: 1 | FR8: 0 | FS8: 0 | FT8: 0 | FU8: 0 | FV8: 0 | FW8: 0 | FX8: 0 | FY8: 0 | FZ8: 0 | GA8: 0 | GB8: 2 | GD8: 0 | GE8: 0 | GF8: 0 | GG8: 0 | GH8: 0 | GI8: 1 | GJ8: 0 | GK8: 0 | GL8: 0 | GM8: 0 | GN8: 0 | GO8: 0 | GP8: 0 | GQ8: 0 | GR8: 0 | GS8: 0 | GT8: 0 | GU8: 0 | GV8: 0 | GW8: 0 | GX8: 0 | GY8: 0 | GZ8: 0 | HA8: 0 | HB8: 0 | HC8: 0 | HD8: 0 | HE8: 0 | HF8: 0 | HG8: 0 | HH8: 0 | HI8: 0 | HJ8: 0 | HK8: 0 | HL8: 0 | HM8: 0 | HN8: 0 | HO8: 0 | HP8: 0 | HQ8: 0 | HR8: 0 | HS8: 0 | HT8: 0 | HU8: 0 | HV8: 0 | HW8: 0 | HX8: 0 | HY8: 0 | HZ8: 0 | IA8: 0 | IB8: 0 | IC8: 0 | ID8: 0 | IE8: 0 | IF8: 0 | IG8: 0 | IH8: 0 | II8: 0 | IJ8: 0 | IK8: 0 | IL8: 0 | IM8: 0 | IN8: 0 | IO8: 0 | IP8: 0 | IQ8: 0 | IS8: 3 | IT8: 0 | IU8: 0 | IV8: 0 | IW8: 0 | IX8: 0 | IY8: 0 | IZ8: marcada
A9: 9 | B9: Fernanda Cortes | C9: Mujer | D9: one | E9: 17 | F9: 25-07-2006 | G9: 24-10-2023 | H9: 07:35 pm | I9: 4 | J9: 4 | K9: 3 | L9: 4 | M9: 4 | N9: 4 | O9: 4 | P9: 4 | Q9: 4 | R9: 4 | S9: 4 | T9: 4 | U9: 4 | V9: 3 | W9: 4 | X9: 4 | Y9: 4 | Z9: 4 | AA9: 2 | AB9: 3 | AC9: 4 | AD9: 4 | AE9: 4 | AF9: 4 | AG9: 2 | AH9: 3 | AI9: 4 | AJ9: 4 | AK9: 4 | AL9: 4 | AM9: 3 | AN9: 3 | AO9: 4 | AP9: 3 | AQ9: 3 | AR9: 3 | AS9: 3 | AT9: 4 | AU9: 4 | AV9: 4 | AW9: 2 | AX9: 3 | AY9: 3 | AZ9: 2 | BA9: 3 | BB9: 2 | BC9: 2 | BD9: 3 | BE9: 4 | BF9: 4 | BG9: 4 | BH9: 4 | BI9: 4 | BJ9: 3 | BK9: 4 | BL9: 4 | BM9: cuando conozco a gente nueva pienso que piensan que soy fea, estupida, que lo les caigo bien, me siento insegura y me da miedo, o cuando pienso en mi futuro, me cuesta mucho concentrarme en la escuela y practicamente en cualquier situacion es como si estuviera pero no estuviera alli | BN9: 3 | BO9: 3 | BP9: 4 | BQ9: 4 | BR9: 4 | BS9: 4 | BT9: 4 | BU9: 4 | BV9: 3 | BW9: 4 | BX9: 4 | BY9: 4 | BZ9: 4 | CA9: 4 | CB9: 4 | CC9: 3 | CD9: 4 | CE9: 3 | CF9: 4 | CG9: 4 | CH9: 4 | CI9: 4 | CJ9: 3 | CK9: 4 | CL9: 4 | CM9: 4 | CN9: 4 | CO9: 4 | CP9: 4 | CQ9: 4 | CR9: 4 | CS9: 3 | CT9: 4 | CU9: 3 | CV9: 4 | CW9: 4 | CX9: 3 | CY9: 4 | CZ9: 4 | DA9: 4 | DB9: 3 | DC9: 2 | DD9: 3 | DE9: 4 | DF9: 4 | DG9: 4 | DH9: 4 | DI9: 4 | DJ9: 4 | DK9: 4 | DL9: 4 | DM9: 4 | DN9: 4 | DO9: 4 | DP9: 4 | DQ9: 4 | DR9: 4 | DS9: 4 | DT9: 4 | DU9: 3 | DV9: 4 | DW9: 4 | DX9: 4 | DY9: 4 | DZ9: 4 | EA9: 4 | EB9: 1 | EC9: 2 | ED9: 1 | EE9: 2 | EF9: 1 | EG9: 1 | EH9: 0 | EI9: 4 | EJ9: 4 | EK9: 4 | EL9: 4 | EM9: 4 | EN9: 2 | EO9: 2 | EP9: 2 | EQ9: 4 | ER9: 2 | ES9: 3 | ET9: 3 | EU9: 3 | EV9: 4 | EW9: 4 | EX9: 4 | EY9: 3 | EZ9: 2 | FA9: 4 | FB9: 3 | FC9: 4 | FD9: 4 | FE9: 2 | FF9: 4 | FG9: 4 | FH9: 4 | FI9: 4 | FJ9: 3 | FK9: 2 | FL9: 3 | FM9: 3 | FN9: 3 | FO9: 3 | FP9: 4 | FQ9: 3 | FR9: 2 | FS9: 2 | FT9: 2 | FU9: 3 | FV9: 4 | FW9: 4 | FX9: 4 | FY9: 4 | FZ9: 4 | GA9: 4 | GB9: 2 | GC9: cuando no me siento real | GD9: 3 | GE9: 3 | GF9: 4 | GG9: 4 | GH9: 4 | GI9: 3 | GJ9: 4 | GK9: 4 | GL9: 3 | GM9: 4 | GN9: 4 | GO9: 4 | GP9: 3 | GQ9: 4 | GR9: 3 | GS9: 4 | GT9: 4 | GU9: 4 | GV9: 4 | GW9: 3 | GX9: 2 | GY9: 4 | GZ9: 3 | HA9: 4 | HB9: 2 | HC9: 4 | HD9: 3 | HE9: 4 | HF9: 3 | HG9: 2 | HH9: 4 | HI9: 4 | HJ9: 4 | HK9: 4 | HL9: 4 | HM9: 4 | HN9: 4 | HO9: 4 | HP9: 4 | HQ9: 3 | HR9: 3 | HS9: 0 | HT9: 0 | HU9: 0 | HV9: 4 | HW9: 4 | HX9: 2 | HY9: 2 | HZ9: 2 | IA9: 4 | IB9: 4 | IC9: 4 | ID9: 4 | IE9: 4 | IF9: 3 | IG9: 3 | IH9: 2 | II9: 4 | IJ9: 2 | IK9: 4 | IL9: 4 | IM9: 3 | IN9: 1 | IO9: 1 | IP9: 1 | IQ9: 1 | IR9: cuando tengo que hacer cosas nuevas o cuando tengo que enfrentarme a algo o alguien | IS9: 4 | IT9: 4 | IU9: 4 | IV9: 4 | IW9: 3 | IX9: 4 | IY9: 4 | IZ9: marcada
A10: 10 | B10: Gabriela Alejandra Zamora Casas | C10: Mujer | D10: two | E10: 43 | F10: 18-04-1980 | G10: 31-10-2023 | H10: 03:15 pm | I10: 3 | J10: 1 | K10: 2 | L10: 2 | M10: 2 | N10: 3 | O10: 2 | P10: 1 | Q10: 1 | R10: 2 | S10: 2 | T10: 1 | U10: 1 | V10: 0 | W10: 2 | X10: 1 | Y10: 2 | Z10: 2 | AA10: 0 | AB10: 0 | AC10: 0 | AD10: 0 | AE10: 1 | AF10: 0 | AG10: 1 | AH10: 0 | AI10: 3 | AJ10: 2 | AK10: 2 | AL10: 2 | AM10: 0 | AN10: 1 | AO10: 3 | AP10: 1 | AQ10: 1 | AR10: 0 | AS10: 0 | AT10: 0 | AU10: 2 | AV10: 0 | AW10: 2 | AX10: 1 | AY10: 1 | AZ10: 2 | BA10: 1 | BB10: 0 | BC10: 0 | BD10: 0 | BE10: 1 | BF10: 3 | BG10: 3 | BH10: 2 | BI10: 2 | BJ10: 2 | BK10: 2 | BL10: 2 | BU10: 0 | BV10: 1 | BW10: 2 | BX10: 0 | BY10: 0 | BZ10: 0 | CA10: 0 | CB10: 2 | CC10: 0 | CD10: 0 | CE10: 1 | CF10: 0 | CG10: 0 | CH10: 0 | CI10: 2 | CJ10: 0 | CK10: 0 | CL10: 2 | CM10: 0 | CN10: 0 | CO10: 1 | CP10: 0 | CQ10: 1 | CR10: 1 | CS10: 1 | CT10: 0 | CU10: 0 | CV10: 2 | CW10: 0 | CX10: 0 | CY10: 0 | CZ10: 0 | DA10: 1 | DB10: 0 | DC10: 0 | DD10: 0 | DE10: 2 | DF10: 0 | DG10: 1 | DH10: 1 | DI10: 0 | DJ10: 1 | DK10: 0 | DL10: 0 | DM10: 0 | DN10: 0 | DO10: 0 | DP10: 0 | DQ10: 0 | DR10: 0 | DS10: 0 | DT10: 0 | DU10: 0 | DV10: 0 | DW10: 0 | DX10: 1 | DY10: 0 | DZ10: 0 | EA10: 0 | EB10: 0 | EC10: 0 | ED10: 0 | EE10: 0 | EF10: 0 | EG10: 0 | EH10: 0 | EI10: 0 | EJ10: 0 | EK10: 1 | EL10: 0 | EM10: 0 | EN10: 0 | EO10: 0 | EP10: 0 | EQ10: 1 | ER10: 0 | ES10: 1 | ET10: 0 | EU10: 0 | EV10: 0 | EW10: 1 | EX10: 0 | EY10: 0 | EZ10: 0 | FA10: 1 | FB10: 0 | FC10: 0 | FD10: 0 | FE10: 0 | FF10: 1 | FG10: 0 | FH10: 0 | FI10: 0 | FJ10: 0 | FK10: 0 | FL10: 0 | FM10: 1 | FN10: 1 | FO10: 0 | FP10: 0 | FQ10: 0 | FR10: 0 | FS10: 0 | FT10: 0 | FU10: 0 | FV10: 0 | FW10: 0 | FX10: 0 | FY10: 0 | FZ10: 0 | GA10: 0 | GB10: 1 | GN10: 0 | GO10: 0 | GP10: 0 | GQ10: 1 | GR10: 0 | GS10: 2 | GT10: 1 | GU10: 1 | GV10: 0 | GW10: 0 | GX10: 0 | GY10: 2 | GZ10: 0 | HA10: 0 | HB10: 1 | HC10: 0 | HD10: 0 | HE10: 0 | HF10: 0 | HG10: 0 | HH10: 0 | HI10: 1 | HJ10: 0 | HK10: 0 | HL10: 0 | HM10: 0 | HN10: 0 | HO10: 0 | HP10: 0 | HQ10: 0 | HR10: 0 | HS10: 0 | HT10: 0 | HU10: 0 | HV10: 2 | HW10: 2 | HX10: 0 | HY10: 0 | HZ10: 0 | IA10: 0 | IB10: 1 | IC10: 0 | ID10: 0 | IE10: 0 | IF10: 0 | IG10: 0 | IH10: 0 | II10: 0 | IJ10: 0 | IK10: 0 | IL10: 0 | IM10: 0 | IN10: 0 | IO10: 0 | IP10: 0 | IQ10: 0 | IS10: 1 | IT10: 0 | IU10: 2 | IV10: 1 | IW10: 0 | IX10: 0 | IY10: 0 | IZ10: marcada
A11: 11 | B11: Iridian Zurizaid Garcia de la Rosa | C11: Mujer | D11: one | E11: 25 | F11: 20-12-2023 | G11: 01-11-2023 | H11: 08:17 am | I11: 2 | J11: 1 | K11: 2 | L11: 3 | M11: 2 | N11: 2 | O11: 2 | P11: 0 | Q11: 1 | R11: 1 | S11: 0 | T11: 2 | U11: 0 | V11: 2 | W11: 0 | X11: 0 | Y11: 0 | Z11: 0 | AA11: 1 | AB11: 1 | AC11: 1 | AD11: 0 | AE11: 1 | AF11: 0 | AG11: 0 | AH11: 0 | AI11: 3 | AJ11: 3 | AK11: 3 | AL11: 2 | AM11: 0 | AN11: 0 | AO11: 1 | AP11: 1 | AQ11: 0 | AR11: 1 | AS11: 1 | AT11: 0 | AU11: 2 | AV11: 2 | AW11: 0 | AX11: 0 | AY11: 0 | AZ11: 0 | BA11: 0 | BB11: 2 | BC11: 0 | BD11: 2 | BE11: 2 | BF11: 0 | BG11: 1 | BH11: 3 | BI11: 3 | BJ11: 1 | BK11: 0 | BL11: 0 | BM11: Cuando voy a un lugar con mucha gente, me siento incómoda, me cuesta concentrarme | BN11: 2 | BO11: 1 | BP11: 1 | BQ11: 2 | BR11: 2 | BS11: 1 | BT11: 0 | BU11: 2 | BV11: 2 | BW11: 2 | BX11: 1 | BY11: 1 | BZ11: 2 | CA11: 0 | CB11: 1 | CC11: 2 | CD11: 2 | CE11: 1 | CF11: 1 | CG11: 1 | CH11: 2 | CI11: 3 | CJ11: 1 | CK11: 1 | CL11: 2 | CM11: 2 | CN11: 2 | CO11: 1 | CP11: 2 | CQ11: 2 | CR11: 1 | CS11: 1 | CT11: 0 | CU11: 0 | CV11: 1 | CW11: 2 | CX11: 1 | CY11: 1 | CZ11: 2 | DA11: 2 | DB11: 1 | DC11: 1 | DD11: 2 | DE11: 1 | DF11: 2 | DG11: 3 | DH11: 2 | DI11: 2 | DJ11: 1 | DK11: 1 | DL11: 1 | DM11: 1 | DN11: 1 | DO11: 1 | DP11: 1 | DQ11: 1 | DR11: 1 | DS11: 1 | DT11: 1 | DU11: 1 | DV11: 1 | DW11: 0 | DX11: 2 | DY11: 1 | DZ11: 1 | EA11: 0 | EB11: 0 | EC11: 0 | ED11: 0 | EE11: 0 | EF11: 0 | EG11: 0 | EH11: 0 | EI11: 2 | EJ11: 3 | EK11: 4 | EL11: 2 | EM11: 1 | EN11: 0 | EO11: 0 | EP11: 0 | EQ11: 1 | ER11: 1 | ES11: 1 | ET11: 1 | EU11: 1 | EV11: 1 | EW11: 1 | EX11: 1 | EY11: 1 | EZ11: 1 | FA11: 1 | FB11: 1 | FC11: 1 | FD11: 2 | FE11: 2 | FF11: 2 | FG11: 2 | FH11: 1 | FI11: 2 | FJ11: 1 | FK11: 0 | FL11: 0 | FM11: 0 | FN11: 0 | FO11: 0 | FP11: 0 | FQ11: 4 | FR11: 3 | FS11: 3 | FT11: 3 | FU11: 2 | FV11: 2 | FW11: 3 | FX11: 2 | FY11: 3 | FZ11: 2 | GA11: 2 | GB11: 2 | GC11: Cuando veo alguna película de terror o suspenso me duele mucho la cabeza, me siento muy nerviosa, me duele el estómago y tengo náuseas | GD11: 3 | GE11: 1 | GF11: 2 | GG11: 3 | GH11: 2 | GI11: 2 | GJ11: 2 | GK11: 2 | GL11: 3 | GM11: 1 | GN11: 4 | GO11: 4 | GP11: 2 | GQ11: 4 | GR11: 4 | GS11: 2 | GT11: 4 | GU11: 4 | GV11: 4 | GW11: 2 | GX11: 2 | GY11: 4 | GZ11: 4 | HA11: 2 | HB11: 2 | HC11: 3 | HD11: 2 | HE11: 2 | HF11: 2 | HG11: 2 | HH11: 4 | HI11: 4 | HJ11: 2 | HK11: 3 | HL11: 2 | HM11: 2 | HN11: 2 | HO11: 4 | HP11: 4 | HQ11: 4 | HR11: 2 | HS11: 0 | HT11: 2 | HU11: 0 | HV11: 4 | HW11: 4 | HX11: 0 | HY11: 0 | HZ11: 1 | IA11: 4 | IB11: 2 | IC11: 1 | ID11: 4 | IE11: 2 | IF11: 4 | IG11: 2 | IH11: 2 | II11: 2 | IJ11: 2 | IK11: 1 | IL11: 1 | IM11: 0 | IN11: 4 | IO11: 4 | IP11: 1 | IQ11: 2 | IR11: Cuando me siento muy tensa, tiendo a cortarme el cabello con las manos y a mover el pie | IS11: 4 | IT11: 4 | IU11: 3 | IV11: 3 | IW11: 4 | IX11: 2 | IY11: 2 | IZ11: marcada
A12: 12 | B12: Karen Sofia Macias Muñoz | C12: Mujer | D12: Unión-Libre | E12: 29 | F12: 24-03-1994 | G12: 15-11-2023 | H12: 11:58 pm | I12: 2 | J12: 3 | K12: 2 | L12: 3 | M12: 1 | N12: 3 | O12: 1 | P12: 0 | Q12: 0 | R12: 1 | S12: 2 | T12: 0 | U12: 0 | V12: 2 | W12: 2 | X12: 0 | Y12: 2 | Z12: 1 | AA12: 3 | AB12: 2 | AC12: 2 | AD12: 0 | AE12: 0 | AF12: 0 | AG12: 0 | AH12: 0 | AI12: 2 | AJ12: 3 | AK12: 1 | AL12: 2 | AM12: 0 | AN12: 1 | AO12: 3 | AP12: 0 | AQ12: 0 | AR12: 0 | AS12: 0 | AT12: 0 | AU12: 1 | AV12: 0 | AW12: 0 | AX12: 0 | AY12: 0 | AZ12: 0 | BA12: 0 | BB12: 0 | BC12: 0 | BD12: 2 | BE12: 2 | BF12: 2 | BG12: 2 | BH12: 2 | BI12: 1 | BJ12: 3 | BK12: 3 | BL12: 0 | BM12: Problemas economicos y con mi pareja | BN12: 3 | BO12: 3 | BP12: 3 | BQ12: 3 | BR12: 3 | BS12: 3 | BT12: 0 | BU12: 1 | BV12: 0 | BW12: 0 | BX12: 0 | BY12: 0 | BZ12: 0 | CA12: 0 | CB12: 0 | CC12: 0 | CD12: 0 | CE12: 0 | CF12: 0 | CG12: 0 | CH12: 0 | CI12: 0 | CJ12: 0 | CK12: 0 | CL12: 1 | CM12: 0 | CN12: 0 | CO12: 0 | CP12: 0 | CQ12: 0 | CR12: 0 | CS12: 0 | CT12: 0 | CU12: 0 | CV12: 0 | CW12: 0 | CX12: 0 | CY12: 0 | CZ12: 0 | DA12: 0 | DB12: 0 | DC12: 0 | DD12: 0 | DE12: 0 | DF12: 0 | DG12: 1 | DH12: 0 | DI12: 0 | DJ12: 0 | DK12: 0 | DL12: 0 | DM12: 0 | DN12: 0 | DO12: 0 | DP12: 0 | DQ12: 0 | DR12: 0 | DS12: 0 | DT12: 0 | DU12: 0 | DV12: 0 | DW12: 0 | DX12: 0 | DY12: 0 | DZ12: 0 | EA12: 0 | EB12: 0 | EC12: 0 | ED12: 0 | EE12: 0 | EF12: 0 | EG12: 0 | EH12: 0 | EI12: 0 | EJ12: 0 | EK12: 1 | EL12: 0 | EM12: 0 | EN12: 0 | EO12: 0 | EP12: 0 | EQ12: 0 | ER12: 0 | ES12: 0 | ET12: 0 | EU12: 0 | EV12: 0 | EW12: 1 | EX12: 0 | EY12: 0 | EZ12: 0 | FA12: 0 | FB12: 0 | FC12: 0 | FD12: 0 | FE12: 0 | FF12: 0 | FG12: 0 | FH12: 0 | FI12: 0 | FJ12: 0 | FK12: 0 | FL12: 0 | FM12: 0 | FN12: 0 | FO12: 0 | FP12: 0 | FQ12: 0 | FR12: 0 | FS12: 0 | FT12: 0 | FU12: 0 | FV12: 0 | FW12: 0 | FX12: 0 | FY12: 0 | FZ12: 0 | GA12: 0 | GB12: 0 | GC12: Cuanto tengo muchas cosas que hacer o se me junta todo | GD12: 0 | GE12: 0 | GF12: 0 | GG12: 3 | GH12: 1 | GI12: 0 | GJ12: 0 | GK12: 0 | GL12: 0 | GM12: 0 | GN12: 2 | GO12: 0 | GP12: 0 | GQ12: 0 | GR12: 0 | GS12: 0 | GT12: 0 | GU12: 3 | GV12: 1 | GW12: 0 | GX12: 0 | GY12: 1 | GZ12: 0 | HA12: 0 | HB12: 0 | HC12: 2 | HD12: 0 | HE12: 0 | HF12: 0 | HG12: 0 | HH12: 0 | HI12: 1 | HJ12: 0 | HK12: 0 | HL12: 0 | HM12: 0 | HN12: 0 | HO12: 2 | HP12: 1 | HQ12: 0 | HR12: 0 | HS12: 0 | HT12: 0 | HU12: 0 | HV12: 0 | HW12: 0 | HX12: 0 | HY12: 0 | HZ12: 0 | IA12: 2 | IB12: 1 | IC12: 0 | ID12: 0 | IE12: 0 | IF12: 0 | IG12: 0 | IH12: 0 | II12: 0 | IJ12: 0 | IK12: 0 | IL12: 0 | IM12: 0 | IN12: 0 | IO12: 0 | IP12: 0 | IQ12: 3 | IR12: Cuando estoy estresada o discuto con mi pareja o me altero con mis hijos | IS12: 3 | IT12: 2 | IU12: 3 | IV12: 2 | IW12: 2 | IX12: 0 | IY12: 0 | IZ12: marcada
